Workbook
Name HOJASDIASDELMES: {"01";"02";"03";"04";"05";"06";"07";"08";"09";"10";"11";"12";"13";"14";"15";"16";"17";"18";"19";"20";"21";"22";"23";"24";"25";"26";"27";"28";"29";"30";"31"}

Sheet Movimiento de Producto
A1: Columna1 | B1: Columna2 | C1: Columna3 | D1: Columna4 | E1: Columna5 | F1: Columna6 | G1: ESTACION ENERGIA ECOFLOW DELTA 3
A2: Fecha | B2: Saldo al Inicio | C2: Entrada | D2: Rotura | E2: Venta | F2: Existencia
A3: 1 | B3: =VLOOKUP(G$1,'01'!B:J,2,0) -> 3 | C3: =VLOOKUP(G$1,'01'!B:J,3,0) -> 0 | D3: =VLOOKUP(G$1,'01'!B:J,4,0) -> 0 | E3: =VLOOKUP(G$1,'01'!B:J,6,0) -> 0 | F3: =B3+C3-E3 -> 3 | G3: =VLOOKUP(G$1,'01'!B:J,8,0) -> 0
A4: 2 | B4: =F3 -> 3 | C4: =VLOOKUP(G$1,'02'!B:J,3,0) -> 0 | D4: =VLOOKUP(G$1,'02'!B:J,4,0) -> 0 | E4: =VLOOKUP(G$1,'02'!B:J,6,0) -> 0 | F4: =B4+C4-E4 -> 3 | G4: =VLOOKUP(G$1,'02'!B:J,8,0) -> 0
A5: 3 | B5: =F4 -> 3 | C5: =VLOOKUP(G$1,'03'!B:J,3,0) -> 0 | D5: =VLOOKUP(G$1,'03'!B:J,4,0) -> 0 | E5: =VLOOKUP(G$1,'03'!B:J,6,0) -> 0 | F5: =B5+C5-E5 -> 3 | G5: =VLOOKUP(G$1,'03'!B:J,8,0) -> 0
A6: 4 | B6: =F5 -> 3 | C6: =VLOOKUP(G$1,'04'!B:J,3,0) -> 0 | D6: =VLOOKUP(G$1,'04'!B:J,4,0) -> 0 | E6: =VLOOKUP(G$1,'04'!B:J,6,0) -> 0 | F6: =B6+C6-E6 -> 3 | G6: =VLOOKUP(G$1,'04'!B:J,8,0) -> 0
A7: 5 | B7: =F6 -> 3 | C7: =VLOOKUP(G$1,'05'!B:J,3,0) -> 0 | D7: =VLOOKUP(G$1,'05'!B:J,4,0) -> 0 | E7: =VLOOKUP(G$1,'05'!B:J,6,0) -> 0 | F7: =B7+C7-E7 -> 3 | G7: =VLOOKUP(G$1,'05'!B:J,8,0) -> 0
A8: 6 | B8: =F7 -> 3 | C8: =VLOOKUP(G$1,'06'!B:J,3,0) -> 0 | D8: =VLOOKUP(G$1,'06'!B:J,4,0) -> 0 | E8: =VLOOKUP(G$1,'06'!B:J,6,0) -> 0 | F8: =B8+C8-E8 -> 3 | G8: =VLOOKUP(G$1,'06'!B:J,8,0) -> 0
A9: 7 | B9: =F8 -> 3 | C9: =VLOOKUP(G$1,'07'!B:J,3,0) -> 0 | D9: =VLOOKUP(G$1,'07'!B:J,4,0) -> 0 | E9: =VLOOKUP(G$1,'07'!B:J,6,0) -> 0 | F9: =B9+C9-E9 -> 3 | G9: =VLOOKUP(G$1,'07'!B:J,8,0) -> 0
A10: 8 | B10: =F9 -> 3 | C10: =VLOOKUP(G$1,'08'!B:J,3,0) -> 0 | D10: =VLOOKUP(G$1,'08'!B:J,4,0) -> 0 | E10: =VLOOKUP(G$1,'08'!B:J,6,0) -> 0 | F10: =B10+C10-E10 -> 3 | G10: =VLOOKUP(G$1,'08'!B:J,8,0) -> 0
A11: 9 | B11: =F10 -> 3 | C11: =VLOOKUP(G$1,'09'!B:J,3,0) -> 0 | D11: =VLOOKUP(G$1,'09'!B:J,4,0) -> 0 | E11: =VLOOKUP(G$1,'09'!B:J,6,0) -> 0 | F11: =B11+C11-E11 -> 3 | G11: =VLOOKUP(G$1,'09'!B:J,8,0) -> 0
A12: 10 | B12: =F11 -> 3 | C12: =VLOOKUP(G$1,'10'!B:J,3,0) -> 0 | D12: =VLOOKUP(G$1,'10'!B:J,4,0) -> 0 | E12: =VLOOKUP(G$1,'10'!B:J,6,0) -> 0 | F12: =B12+C12-E12 -> 3 | G12: =VLOOKUP(G$1,'10'!B:J,8,0) -> 0
A13: 11 | B13: =F12 -> 3 | C13: =VLOOKUP(G$1,'11'!B:J,3,0) -> 0 | D13: =VLOOKUP(G$1,'11'!B:J,4,0) -> 0 | E13: =VLOOKUP(G$1,'11'!B:J,6,0) -> 0 | F13: =B13+C13-E13 -> 3 | G13: =VLOOKUP(G$1,'11'!B:J,8,0) -> 0
A14: 12 | B14: =F13 -> 3 | C14: =VLOOKUP(G$1,'12'!B:J,3,0) -> 0 | D14: =VLOOKUP(G$1,'12'!B:J,4,0) -> 0 | E14: =VLOOKUP(G$1,'12'!B:J,6,0) -> 0 | F14: =B14+C14-E14 -> 3 | G14: =VLOOKUP(G$1,'12'!B:J,8,0) -> 0
A15: 13 | B15: =F14 -> 3 | C15: =VLOOKUP(G$1,'13'!B:J,3,0) -> 0 | D15: =VLOOKUP(G$1,'13'!B:J,4,0) -> 0 | E15: =VLOOKUP(G$1,'13'!B:J,6,0) -> 0 | F15: =B15+C15-E15 -> 3 | G15: =VLOOKUP(G$1,'13'!B:J,8,0) -> 0
A16: 14 | B16: =F15 -> 3 | C16: =VLOOKUP(G$1,'14'!B:J,3,0) -> 0 | D16: =VLOOKUP(G$1,'14'!B:J,4,0) -> 0 | E16: =VLOOKUP(G$1,'14'!B:J,6,0) -> 0 | F16: =B16+C16-E16 -> 3 | G16: =VLOOKUP(G$1,'14'!B:J,8,0) -> 0
A17: 15 | B17: =F16 -> 3 | C17: =VLOOKUP(G$1,'15'!B:J,3,0) -> 0 | D17: =VLOOKUP(G$1,'15'!B:J,4,0) -> 0 | E17: =VLOOKUP(G$1,'15'!B:J,6,0) -> 0 | F17: =B17+C17-E17 -> 3 | G17: =VLOOKUP(G$1,'15'!B:J,8,0) -> 0
A18: 16 | B18: =F17 -> 3 | C18: =VLOOKUP(G$1,'16'!B:J,3,0) -> 0 | D18: =VLOOKUP(G$1,'16'!B:J,4,0) -> 0 | E18: =VLOOKUP(G$1,'16'!B:J,6,0) -> 0 | F18: =B18+C18-E18 -> 3 | G18: =VLOOKUP(G$1,'16'!B:J,8,0) -> 0
A19: 17 | B19: =F18 -> 3 | C19: =VLOOKUP(G$1,'17'!B:J,3,0) -> 0 | D19: =VLOOKUP(G$1,'17'!B:J,4,0) -> 0 | E19: =VLOOKUP(G$1,'17'!B:J,6,0) -> 0 | F19: =B19+C19-E19 -> 3 | G19: =VLOOKUP(G$1,'17'!B:J,8,0) -> 0
A20: 18 | B20: =F19 -> 3 | C20: =VLOOKUP(G$1,'18'!B:J,3,0) -> 0 | D20: =VLOOKUP(G$1,'18'!B:J,4,0) -> 0 | E20: =VLOOKUP(G$1,'18'!B:J,6,0) -> 0 | F20: =B20+C20-E20 -> 3 | G20: =VLOOKUP(G$1,'18'!B:J,8,0) -> 0
A21: 19 | B21: =F20 -> 3 | C21: =VLOOKUP(G$1,'19'!B:J,3,0) -> 0 | D21: =VLOOKUP(G$1,'19'!B:J,4,0) -> 0 | E21: =VLOOKUP(G$1,'19'!B:J,6,0) -> 0 | F21: =B21+C21-E21 -> 3 | G21: =VLOOKUP(G$1,'19'!B:J,8,0) -> 0
A22: 20 | B22: =F21 -> 3 | C22: =VLOOKUP(G$1,'20'!B:J,3,0) -> 0 | D22: =VLOOKUP(G$1,'20'!B:J,4,0) -> 0 | E22: =VLOOKUP(G$1,'20'!B:J,6,0) -> 0 | F22: =B22+C22-E22 -> 3 | G22: =VLOOKUP(G$1,'20'!B:J,8,0) -> 0
A23: 21 | B23: =F22 -> 3 | C23: =VLOOKUP(G$1,'21'!B:J,3,0) -> 0 | D23: =VLOOKUP(G$1,'21'!B:J,4,0) -> 0 | E23: =VLOOKUP(G$1,'21'!B:J,6,0) -> 0 | F23: =B23+C23-E23 -> 3 | G23: =VLOOKUP(G$1,'21'!B:J,8,0) -> 0
A24: 22 | B24: =F23 -> 3 | C24: =VLOOKUP(G$1,'22'!B:J,3,0) -> 0 | D24: =VLOOKUP(G$1,'22'!B:J,4,0) -> 0 | E24: =VLOOKUP(G$1,'22'!B:J,6,0) -> 0 | F24: =B24+C24-E24 -> 3 | G24: =VLOOKUP(G$1,'22'!B:J,8,0) -> 0
A25: 23 | B25: =F24 -> 3 | C25: =VLOOKUP(G$1,'23'!B:J,3,0) -> 0 | D25: =VLOOKUP(G$1,'23'!B:J,4,0) -> 0 | E25: =VLOOKUP(G$1,'23'!B:J,6,0) -> 0 | F25: =B25+C25-E25 -> 3 | G25: =VLOOKUP(G$1,'23'!B:J,8,0) -> 0
A26: 24 | B26: =F25 -> 3 | C26: =VLOOKUP(G$1,'24'!B:J,3,0) -> 0 | D26: =VLOOKUP(G$1,'24'!B:J,4,0) -> 0 | E26: =VLOOKUP(G$1,'24'!B:J,6,0) -> 0 | F26: =B26+C26-E26 -> 3 | G26: =VLOOKUP(G$1,'24'!B:J,8,0) -> 0
A27: 25 | B27: =F26 -> 3 | C27: =VLOOKUP(G$1,'25'!B:J,3,0) -> 0 | D27: =VLOOKUP(G$1,'25'!B:J,4,0) -> 0 | E27: =VLOOKUP(G$1,'25'!B:J,6,0) -> 0 | F27: =B27+C27-E27 -> 3 | G27: =VLOOKUP(G$1,'25'!B:J,8,0) -> 0
A28: 26 | B28: =F27 -> 3 | C28: =VLOOKUP(G$1,'26'!B:J,3,0) -> 0 | D28: =VLOOKUP(G$1,'26'!B:J,4,0) -> 0 | E28: =VLOOKUP(G$1,'26'!B:J,6,0) -> 0 | F28: =B28+C28-E28 -> 3 | G28: =VLOOKUP(G$1,'26'!B:J,8,0) -> 0
A29: 27 | B29: =F28 -> 3 | C29: =VLOOKUP(G$1,'27'!B:J,3,0) -> 0 | D29: =VLOOKUP(G$1,'27'!B:J,4,0) -> 0 | E29: =VLOOKUP(G$1,'27'!B:J,6,0) -> 0 | F29: =B29+C29-E29 -> 3 | G29: =VLOOKUP(G$1,'27'!B:J,8,0) -> 0
A30: 28 | B30: =F29 -> 3 | C30: =VLOOKUP(G$1,'28'!B:J,3,0) -> 0 | D30: =VLOOKUP(G$1,'28'!B:J,4,0) -> 0 | E30: =VLOOKUP(G$1,'28'!B:J,6,0) -> 0 | F30: =B30+C30-E30 -> 3 | G30: =VLOOKUP(G$1,'28'!B:J,8,0) -> 0
A31: 29 | B31: =F30 -> 3 | C31: =VLOOKUP(G$1,'29'!B:J,3,0) -> 0 | D31: =VLOOKUP(G$1,'29'!B:J,4,0) -> 0 | E31: =VLOOKUP(G$1,'29'!B:J,6,0) -> 0 | F31: =B31+C31-E31 -> 3 | G31: =VLOOKUP(G$1,'29'!B:J,8,0) -> 0
A32: 30 | B32: =F31 -> 3 | C32: =VLOOKUP(G$1,'30'!B:J,3,0) -> 0 | D32: =VLOOKUP(G$1,'30'!B:J,4,0) -> 0 | E32: =VLOOKUP(G$1,'30'!B:J,6,0) -> 0 | F32: =B32+C32-E32 -> 3 | G32: =VLOOKUP(G$1,'30'!B:J,8,0) -> 0
A33: 31 | B33: =F32 -> 3 | C33: =VLOOKUP(G$1,'31'!B:J,3,0) -> 0 | D33: =VLOOKUP(G$1,'31'!B:J,4,0) -> 0 | E33: =VLOOKUP(G$1,'31'!B:J,6,0) -> 0 | F33: =B33+C33-E33 -> 3 | G33: =VLOOKUP(G$1,'31'!B:J,8,0) -> 0
A34: Total | B34: =B3 -> 3 | C34: =SUBTOTAL(109,Tabla1[Columna3]) -> 0 | D34: =SUBTOTAL(109,Tabla1[Columna4]) -> 0 | E34: =SUBTOTAL(109,Tabla1[Columna5]) -> 0 | F34: =F33 -> 3 | G34: =SUBTOTAL(109,Tabla1[ESTACION ENERGIA ECOFLOW DELTA 3]) -> 0

Sheet Estadística
B3: CONTROL DE INVENTARIO | F3: ÁREA: | G3: NOVA | K3: PUNTO DE VENTA: La Ola
B4: A PRECIO DE VENTA | K4: Período: | L4: =TODAY() -> 46296
F5: No, | K5: =SUBTOTAL(9,K9:K399) -> 118
C6: Venta Semana 1 | E6: Venta Semana 2 | G6: Venta Semana 3 | I6: Venta Semana 4 | K6: Venta Prom./Día | M6: Venta Prom./Semana | O6: Venta Estim./Mes
A7: UM | B7: DETALLE | C7: Físico | D7: Importe | E7: Físico | F7: Importe | G7: Físico | H7: Importe | I7: Físico | J7: Importe | K7: Físico | L7: Importe | M7: Físico | N7: Importe | O7: Físico | P7: Importe
A8: A | B8: B | C8: C | D8: D | E8: E | F8: F | G8: G | H8: H | I8: I | J8: J | K8: K | L8: L | M8: K | N8: L | O8: K | P8: L
A9: U | B9: BOLSA DE CEMENTO BLANCO | C9: =SUM(SUMIF(INDIRECT({"01";"02";"03";"04";"05";"06";"07"} & "!B:G"),$B9,INDIRECT({"01";"02";"03";"04";"05";"06";"07"} & "!G:G"))) -> 0 | D9: =SUM(SUMIF(INDIRECT({"01";"02";"03";"04";"05";"06";"07"} & "!B:I"),$B9,INDIRECT({"01";"02";"03";"04";"05";"06";"07"} & "!I:I"))) -> 0 | E9: {=SUM(SUMIF(INDIRECT({"08";"09";"10";"11";"12";"13";"14"} & "!B:G"),$B9,INDIRECT({"08";"09";"10";"11";"12";"13";"14"} & "!G:G")))} -> 0 | F9: {=SUM(SUMIF(INDIRECT({"08";"09";"10";"11";"12";"13";"14"} & "!B:I"),$B9,INDIRECT({"08";"09";"10";"11";"12";"13";"14"} & "!I:I")))} -> 0 | G9: {=SUM(SUMIF(INDIRECT({"15";"16";"17";"18";"19";"20";"21"} & "!B:G"),$B9,INDIRECT({"15";"16";"17";"18";"19";"20";"21"} & "!G:G")))} -> 0 | H9: {=SUM(SUMIF(INDIRECT({"15";"16";"17";"18";"19";"20";"21"} & "!B:I"),$B9,INDIRECT({"15";"16";"17";"18";"19";"20";"21"} & "!I:I")))} -> 0 | I9: {=SUM(SUMIF(INDIRECT({"22";"23";"24";"25";"26";"27";"28";"29";"30";"31"} & "!B:G"),$B9,INDIRECT({"22";"23";"24";"25";"26";"27";"28";"29";"30";"31"} & "!G:G")))} -> 0 | J9: {=SUM(SUMIF(INDIRECT({"22";"23";"24";"25";"26";"27";"28";"29";"30";"31"} & "!B:I"),$B9,INDIRECT({"22";"23";"24";"25";"26";"27";"28";"29";"30";"31"} & "!I:I")))} -> 0 | K9: =ROUND(SUM(C9,E9,G9,I9)/DAY(TODAY()),0) -> 0 | L9: =SUM(D9,F9,H9,J9)/DAY(TODAY()) -> 0 | M9: =K9*7 -> 0 | N9: =L9*7 -> 0 | O9: =ROUND(K9*30,0) -> 0 | P9: =L9*30 -> 0 | S9: =EXACT(B9,Total!B9) -> TRUE | T9: =SUM(D9+F9+H9+J9) -> 0 | W9: BOLSA DE CEMENTO BLANCO
A10: U | B10: SACO DE CEMENTO GRIS P350 | C10: =SUM(SUMIF(INDIRECT({"01";"02";"03";"04";"05";"06";"07"} & "!B:G"),$B10,INDIRECT({"01";"02";"03";"04";"05";"06";"07"} & "!G:G"))) -> 0 | D10: =SUM(SUMIF(INDIRECT({"01";"02";"03";"04";"05";"06";"07"} & "!B:I"),$B10,INDIRECT({"01";"02";"03";"04";"05";"06";"07"} & "!I:I"))) -> 0 | E10: {=SUM(SUMIF(INDIRECT({"08";"09";"10";"11";"12";"13";"14"} & "!B:G"),$B10,INDIRECT({"08";"09";"10";"11";"12";"13";"14"} & "!G:G")))} -> 5 | F10: {=SUM(SUMIF(INDIRECT({"08";"09";"10";"11";"12";"13";"14"} & "!B:I"),$B10,INDIRECT({"08";"09";"10";"11";"12";"13";"14"} & "!I:I")))} -> 150 | G10: {=SUM(SUMIF(INDIRECT({"15";"16";"17";"18";"19";"20";"21"} & "!B:G"),$B10,INDIRECT({"15";"16";"17";"18";"19";"20";"21"} & "!G:G")))} -> 0 | H10: {=SUM(SUMIF(INDIRECT({"15";"16";"17";"18";"19";"20";"21"} & "!B:I"),$B10,INDIRECT({"15";"16";"17";"18";"19";"20";"21"} & "!I:I")))} -> 0 | I10: {=SUM(SUMIF(INDIRECT({"22";"23";"24";"25";"26";"27";"28";"29";"30";"31"} & "!B:G"),$B10,INDIRECT({"22";"23";"24";"25";"26";"27";"28";"29";"30";"31"} & "!G:G")))} -> 0 | J10: {=SUM(SUMIF(INDIRECT({"22";"23";"24";"25";"26";"27";"28";"29";"30";"31"} & "!B:I"),$B10,INDIRECT({"22";"23";"24";"25";"26";"27";"28";"29";"30";"31"} & "!I:I")))} -> 0 | K10: =ROUND(SUM(C10,E10,G10,I10)/DAY(TODAY()),0) -> 5 | L10: =SUM(D10,F10,H10,J10)/DAY(TODAY()) -> 150 | M10: =K10*7 -> 35 | N10: =L10*7 -> 1050 | O10: =ROUND(K10*30,0) -> 150 | P10: =L10*30 -> 4500 | S10: =EXACT(B10,Total!B10) -> TRUE | T10: =SUM(D10+F10+H10+J10) -> 150 | W10: SACO DE CEMENTO GRIS P350
B11: BATERIA 5K MUST | C11: =SUM(SUMIF(INDIRECT({"01";"02";"03";"04";"05";"06";"07"} & "!B:G"),$B11,INDIRECT({"01";"02";"03";"04";"05";"06";"07"} & "!G:G"))) -> 2 | D11: =SUM(SUMIF(INDIRECT({"01";"02";"03";"04";"05";"06";"07"} & "!B:I"),$B11,INDIRECT({"01";"02";"03";"04";"05";"06";"07"} & "!I:I"))) -> 3200 | E11: {=SUM(SUMIF(INDIRECT({"08";"09";"10";"11";"12";"13";"14"} & "!B:G"),$B11,INDIRECT({"08";"09";"10";"11";"12";"13";"14"} & "!G:G")))} -> 0 | F11: {=SUM(SUMIF(INDIRECT({"08";"09";"10";"11";"12";"13";"14"} & "!B:I"),$B11,INDIRECT({"08";"09";"10";"11";"12";"13";"14"} & "!I:I")))} -> 0 | G11: {=SUM(SUMIF(INDIRECT({"15";"16";"17";"18";"19";"20";"21"} & "!B:G"),$B11,INDIRECT({"15";"16";"17";"18";"19";"20";"21"} & "!G:G")))} -> 0 | H11: {=SUM(SUMIF(INDIRECT({"15";"16";"17";"18";"19";"20";"21"} & "!B:I"),$B11,INDIRECT({"15";"16";"17";"18";"19";"20";"21"} & "!I:I")))} -> 0 | I11: {=SUM(SUMIF(INDIRECT({"22";"23";"24";"25";"26";"27";"28";"29";"30";"31"} & "!B:G"),$B11,INDIRECT({"22";"23";"24";"25";"26";"27";"28";"29";"30";"31"} & "!G:G")))} -> 0 | J11: {=SUM(SUMIF(INDIRECT({"22";"23";"24";"25";"26";"27";"28";"29";"30";"31"} & "!B:I"),$B11,INDIRECT({"22";"23";"24";"25";"26";"27";"28";"29";"30";"31"} & "!I:I")))} -> 0 | K11: =ROUND(SUM(C11,E11,G11,I11)/DAY(TODAY()),0) -> 2 | L11: =SUM(D11,F11,H11,J11)/DAY(TODAY()) -> 3200 | M11: =K11*7 -> 14 | N11: =L11*7 -> 22400 | O11: =ROUND(K11*30,0) -> 60 | P11: =L11*30 -> 96000 | S11: =EXACT(B11,Total!B11) -> TRUE | T11: =SUM(D11+F11+H11+J11) -> 3200 | W11: BATERIA 5K MUST
B12: BATERIA HUMSIENK 24V 200AMP | C12: =SUM(SUMIF(INDIRECT({"01";"02";"03";"04";"05";"06";"07"} & "!B:G"),$B12,INDIRECT({"01";"02";"03";"04";"05";"06";"07"} & "!G:G"))) -> 0 | D12: =SUM(SUMIF(INDIRECT({"01";"02";"03";"04";"05";"06";"07"} & "!B:I"),$B12,INDIRECT({"01";"02";"03";"04";"05";"06";"07"} & "!I:I"))) -> 0 | E12: {=SUM(SUMIF(INDIRECT({"08";"09";"10";"11";"12";"13";"14"} & "!B:G"),$B12,INDIRECT({"08";"09";"10";"11";"12";"13";"14"} & "!G:G")))} -> 0 | F12: {=SUM(SUMIF(INDIRECT({"08";"09";"10";"11";"12";"13";"14"} & "!B:I"),$B12,INDIRECT({"08";"09";"10";"11";"12";"13";"14"} & "!I:I")))} -> 0 | G12: {=SUM(SUMIF(INDIRECT({"15";"16";"17";"18";"19";"20";"21"} & "!B:G"),$B12,INDIRECT({"15";"16";"17";"18";"19";"20";"21"} & "!G:G")))} -> 0 | H12: {=SUM(SUMIF(INDIRECT({"15";"16";"17";"18";"19";"20";"21"} & "!B:I"),$B12,INDIRECT({"15";"16";"17";"18";"19";"20";"21"} & "!I:I")))} -> 0 | I12: {=SUM(SUMIF(INDIRECT({"22";"23";"24";"25";"26";"27";"28";"29";"30";"31"} & "!B:G"),$B12,INDIRECT({"22";"23";"24";"25";"26";"27";"28";"29";"30";"31"} & "!G:G")))} -> 0 | J12: {=SUM(SUMIF(INDIRECT({"22";"23";"24";"25";"26";"27";"28";"29";"30";"31"} & "!B:I"),$B12,INDIRECT({"22";"23";"24";"25";"26";"27";"28";"29";"30";"31"} & "!I:I")))} -> 0 | K12: =ROUND(SUM(C12,E12,G12,I12)/DAY(TODAY()),0) -> 0 | L12: =SUM(D12,F12,H12,J12)/DAY(TODAY()) -> 0 | M12: =K12*7 -> 0 | N12: =L12*7 -> 0 | O12: =ROUND(K12*30,0) -> 0 | P12: =L12*30 -> 0 | S12: =EXACT(B12,Total!B12) -> TRUE | T12: =SUM(D12+F12+H12+J12) -> 0 | W12: BATERIA HUMSIENK 24V 200AMP
A13: U | B13: BATERIA DE 12V 100A JMD | C13: =SUM(SUMIF(INDIRECT({"01";"02";"03";"04";"05";"06";"07"} & "!B:G"),$B13,INDIRECT({"01";"02";"03";"04";"05";"06";"07"} & "!G:G"))) -> 0 | D13: =SUM(SUMIF(INDIRECT({"01";"02";"03";"04";"05";"06";"07"} & "!B:I"),$B13,INDIRECT({"01";"02";"03";"04";"05";"06";"07"} & "!I:I"))) -> 0 | E13: {=SUM(SUMIF(INDIRECT({"08";"09";"10";"11";"12";"13";"14"} & "!B:G"),$B13,INDIRECT({"08";"09";"10";"11";"12";"13";"14"} & "!G:G")))} -> 0 | F13: {=SUM(SUMIF(INDIRECT({"08";"09";"10";"11";"12";"13";"14"} & "!B:I"),$B13,INDIRECT({"08";"09";"10";"11";"12";"13";"14"} & "!I:I")))} -> 0 | G13: {=SUM(SUMIF(INDIRECT({"15";"16";"17";"18";"19";"20";"21"} & "!B:G"),$B13,INDIRECT({"15";"16";"17";"18";"19";"20";"21"} & "!G:G")))} -> 0 | H13: {=SUM(SUMIF(INDIRECT({"15";"16";"17";"18";"19";"20";"21"} & "!B:I"),$B13,INDIRECT({"15";"16";"17";"18";"19";"20";"21"} & "!I:I")))} -> 0 | I13: {=SUM(SUMIF(INDIRECT({"22";"23";"24";"25";"26";"27";"28";"29";"30";"31"} & "!B:G"),$B13,INDIRECT({"22";"23";"24";"25";"26";"27";"28";"29";"30";"31"} & "!G:G")))} -> 0 | J13: {=SUM(SUMIF(INDIRECT({"22";"23";"24";"25";"26";"27";"28";"29";"30";"31"} & "!B:I"),$B13,INDIRECT({"22";"23";"24";"25";"26";"27";"28";"29";"30";"31"} & "!I:I")))} -> 0 | K13: =ROUND(SUM(C13,E13,G13,I13)/DAY(TODAY()),0) -> 0 | L13: =SUM(D13,F13,H13,J13)/DAY(TODAY()) -> 0 | M13: =K13*7 -> 0 | N13: =L13*7 -> 0 | O13: =ROUND(K13*30,0) -> 0 | P13: =L13*30 -> 0 | S13: =EXACT(B13,Total!B13) -> TRUE | T13: =SUM(D13+F13+H13+J13) -> 0 | W13: BATERIA DE 12V 100A JMD
B14: BATERIA DE 12V 150A SACO | C14: =SUM(SUMIF(INDIRECT({"01";"02";"03";"04";"05";"06";"07"} & "!B:G"),$B14,INDIRECT({"01";"02";"03";"04";"05";"06";"07"} & "!G:G"))) -> 0 | D14: =SUM(SUMIF(INDIRECT({"01";"02";"03";"04";"05";"06";"07"} & "!B:I"),$B14,INDIRECT({"01";"02";"03";"04";"05";"06";"07"} & "!I:I"))) -> 0 | E14: {=SUM(SUMIF(INDIRECT({"08";"09";"10";"11";"12";"13";"14"} & "!B:G"),$B14,INDIRECT({"08";"09";"10";"11";"12";"13";"14"} & "!G:G")))} -> 0 | F14: {=SUM(SUMIF(INDIRECT({"08";"09";"10";"11";"12";"13";"14"} & "!B:I"),$B14,INDIRECT({"08";"09";"10";"11";"12";"13";"14"} & "!I:I")))} -> 0 | G14: {=SUM(SUMIF(INDIRECT({"15";"16";"17";"18";"19";"20";"21"} & "!B:G"),$B14,INDIRECT({"15";"16";"17";"18";"19";"20";"21"} & "!G:G")))} -> 1 | H14: {=SUM(SUMIF(INDIRECT({"15";"16";"17";"18";"19";"20";"21"} & "!B:I"),$B14,INDIRECT({"15";"16";"17";"18";"19";"20";"21"} & "!I:I")))} -> 500 | I14: {=SUM(SUMIF(INDIRECT({"22";"23";"24";"25";"26";"27";"28";"29";"30";"31"} & "!B:G"),$B14,INDIRECT({"22";"23";"24";"25";"26";"27";"28";"29";"30";"31"} & "!G:G")))} -> 0 | J14: {=SUM(SUMIF(INDIRECT({"22";"23";"24";"25";"26";"27";"28";"29";"30";"31"} & "!B:I"),$B14,INDIRECT({"22";"23";"24";"25";"26";"27";"28";"29";"30";"31"} & "!I:I")))} -> 0 | K14: =ROUND(SUM(C14,E14,G14,I14)/DAY(TODAY()),0) -> 1 | L14: =SUM(D14,F14,H14,J14)/DAY(TODAY()) -> 500 | M14: =K14*7 -> 7 | N14: =L14*7 -> 3500 | O14: =ROUND(K14*30,0) -> 30 | P14: =L14*30 -> 15000 | S14: =EXACT(B14,Total!B14) -> TRUE | T14: =SUM(D14+F14+H14+J14) -> 500 | W14: BATERIA DE 12V 150A SACO
A15: U | B15: BATERIA EXTRA 16K SACO | C15: =SUM(SUMIF(INDIRECT({"01";"02";"03";"04";"05";"06";"07"} & "!B:G"),$B15,INDIRECT({"01";"02";"03";"04";"05";"06";"07"} & "!G:G"))) -> 0 | D15: =SUM(SUMIF(INDIRECT({"01";"02";"03";"04";"05";"06";"07"} & "!B:I"),$B15,INDIRECT({"01";"02";"03";"04";"05";"06";"07"} & "!I:I"))) -> 0 | E15: {=SUM(SUMIF(INDIRECT({"08";"09";"10";"11";"12";"13";"14"} & "!B:G"),$B15,INDIRECT({"08";"09";"10";"11";"12";"13";"14"} & "!G:G")))} -> 0 | F15: {=SUM(SUMIF(INDIRECT({"08";"09";"10";"11";"12";"13";"14"} & "!B:I"),$B15,INDIRECT({"08";"09";"10";"11";"12";"13";"14"} & "!I:I")))} -> 0 | G15: {=SUM(SUMIF(INDIRECT({"15";"16";"17";"18";"19";"20";"21"} & "!B:G"),$B15,INDIRECT({"15";"16";"17";"18";"19";"20";"21"} & "!G:G")))} -> 0 | H15: {=SUM(SUMIF(INDIRECT({"15";"16";"17";"18";"19";"20";"21"} & "!B:I"),$B15,INDIRECT({"15";"16";"17";"18";"19";"20";"21"} & "!I:I")))} -> 0 | I15: {=SUM(SUMIF(INDIRECT({"22";"23";"24";"25";"26";"27";"28";"29";"30";"31"} & "!B:G"),$B15,INDIRECT({"22";"23";"24";"25";"26";"27";"28";"29";"30";"31"} & "!G:G")))} -> 0 | J15: {=SUM(SUMIF(INDIRECT({"22";"23";"24";"25";"26";"27";"28";"29";"30";"31"} & "!B:I"),$B15,INDIRECT({"22";"23";"24";"25";"26";"27";"28";"29";"30";"31"} & "!I:I")))} -> 0 | K15: =ROUND(SUM(C15,E15,G15,I15)/DAY(TODAY()),0) -> 0 | L15: =SUM(D15,F15,H15,J15)/DAY(TODAY()) -> 0 | M15: =K15*7 -> 0 | N15: =L15*7 -> 0 | O15: =ROUND(K15*30,0) -> 0 | P15: =L15*30 -> 0 | S15: =EXACT(B15,Total!B15) -> TRUE | T15: =SUM(D15+F15+H15+J15) -> 0 | W15: BATERIA EXTRA 16K SACO
A16: U | B16: BASE PARA PANELES GRANDES | C16: =SUM(SUMIF(INDIRECT({"01";"02";"03";"04";"05";"06";"07"} & "!B:G"),$B16,INDIRECT({"01";"02";"03";"04";"05";"06";"07"} & "!G:G"))) -> 0 | D16: =SUM(SUMIF(INDIRECT({"01";"02";"03";"04";"05";"06";"07"} & "!B:I"),$B16,INDIRECT({"01";"02";"03";"04";"05";"06";"07"} & "!I:I"))) -> 0 | E16: {=SUM(SUMIF(INDIRECT({"08";"09";"10";"11";"12";"13";"14"} & "!B:G"),$B16,INDIRECT({"08";"09";"10";"11";"12";"13";"14"} & "!G:G")))} -> 0 | F16: {=SUM(SUMIF(INDIRECT({"08";"09";"10";"11";"12";"13";"14"} & "!B:I"),$B16,INDIRECT({"08";"09";"10";"11";"12";"13";"14"} & "!I:I")))} -> 0 | G16: {=SUM(SUMIF(INDIRECT({"15";"16";"17";"18";"19";"20";"21"} & "!B:G"),$B16,INDIRECT({"15";"16";"17";"18";"19";"20";"21"} & "!G:G")))} -> 0 | H16: {=SUM(SUMIF(INDIRECT({"15";"16";"17";"18";"19";"20";"21"} & "!B:I"),$B16,INDIRECT({"15";"16";"17";"18";"19";"20";"21"} & "!I:I")))} -> 0 | I16: {=SUM(SUMIF(INDIRECT({"22";"23";"24";"25";"26";"27";"28";"29";"30";"31"} & "!B:G"),$B16,INDIRECT({"22";"23";"24";"25";"26";"27";"28";"29";"30";"31"} & "!G:G")))} -> 0 | J16: {=SUM(SUMIF(INDIRECT({"22";"23";"24";"25";"26";"27";"28";"29";"30";"31"} & "!B:I"),$B16,INDIRECT({"22";"23";"24";"25";"26";"27";"28";"29";"30";"31"} & "!I:I")))} -> 0 | K16: =ROUND(SUM(C16,E16,G16,I16)/DAY(TODAY()),0) -> 0 | L16: =SUM(D16,F16,H16,J16)/DAY(TODAY()) -> 0 | M16: =K16*7 -> 0 | N16: =L16*7 -> 0 | O16: =ROUND(K16*30,0) -> 0 | P16: =L16*30 -> 0 | S16: =EXACT(B16,Total!B16) -> TRUE | T16: =SUM(D16+F16+H16+J16) -> 0 | W16: BASE PARA PANELES GRANDES
A17: U | B17: BASE PARA PANELES | C17: =SUM(SUMIF(INDIRECT({"01";"02";"03";"04";"05";"06";"07"} & "!B:G"),$B17,INDIRECT({"01";"02";"03";"04";"05";"06";"07"} & "!G:G"))) -> 0 | D17: =SUM(SUMIF(INDIRECT({"01";"02";"03";"04";"05";"06";"07"} & "!B:I"),$B17,INDIRECT({"01";"02";"03";"04";"05";"06";"07"} & "!I:I"))) -> 0 | E17: {=SUM(SUMIF(INDIRECT({"08";"09";"10";"11";"12";"13";"14"} & "!B:G"),$B17,INDIRECT({"08";"09";"10";"11";"12";"13";"14"} & "!G:G")))} -> 0 | F17: {=SUM(SUMIF(INDIRECT({"08";"09";"10";"11";"12";"13";"14"} & "!B:I"),$B17,INDIRECT({"08";"09";"10";"11";"12";"13";"14"} & "!I:I")))} -> 0 | G17: {=SUM(SUMIF(INDIRECT({"15";"16";"17";"18";"19";"20";"21"} & "!B:G"),$B17,INDIRECT({"15";"16";"17";"18";"19";"20";"21"} & "!G:G")))} -> 0 | H17: {=SUM(SUMIF(INDIRECT({"15";"16";"17";"18";"19";"20";"21"} & "!B:I"),$B17,INDIRECT({"15";"16";"17";"18";"19";"20";"21"} & "!I:I")))} -> 0 | I17: {=SUM(SUMIF(INDIRECT({"22";"23";"24";"25";"26";"27";"28";"29";"30";"31"} & "!B:G"),$B17,INDIRECT({"22";"23";"24";"25";"26";"27";"28";"29";"30";"31"} & "!G:G")))} -> 0 | J17: {=SUM(SUMIF(INDIRECT({"22";"23";"24";"25";"26";"27";"28";"29";"30";"31"} & "!B:I"),$B17,INDIRECT({"22";"23";"24";"25";"26";"27";"28";"29";"30";"31"} & "!I:I")))} -> 0 | K17: =ROUND(SUM(C17,E17,G17,I17)/DAY(TODAY()),0) -> 0 | L17: =SUM(D17,F17,H17,J17)/DAY(TODAY()) -> 0 | M17: =K17*7 -> 0 | N17: =L17*7 -> 0 | O17: =ROUND(K17*30,0) -> 0 | P17: =L17*30 -> 0 | S17: =EXACT(B17,Total!B17) -> TRUE | T17: =SUM(D17+F17+H17+J17) -> 0 | W17: BASE PARA PANELES
A18: U | B18: BASE FIJA PARA TV 32'' - 86'' | C18: =SUM(SUMIF(INDIRECT({"01";"02";"03";"04";"05";"06";"07"} & "!B:G"),$B18,INDIRECT({"01";"02";"03";"04";"05";"06";"07"} & "!G:G"))) -> 0 | D18: =SUM(SUMIF(INDIRECT({"01";"02";"03";"04";"05";"06";"07"} & "!B:I"),$B18,INDIRECT({"01";"02";"03";"04";"05";"06";"07"} & "!I:I"))) -> 0 | E18: {=SUM(SUMIF(INDIRECT({"08";"09";"10";"11";"12";"13";"14"} & "!B:G"),$B18,INDIRECT({"08";"09";"10";"11";"12";"13";"14"} & "!G:G")))} -> 1 | F18: {=SUM(SUMIF(INDIRECT({"08";"09";"10";"11";"12";"13";"14"} & "!B:I"),$B18,INDIRECT({"08";"09";"10";"11";"12";"13";"14"} & "!I:I")))} -> 20 | G18: {=SUM(SUMIF(INDIRECT({"15";"16";"17";"18";"19";"20";"21"} & "!B:G"),$B18,INDIRECT({"15";"16";"17";"18";"19";"20";"21"} & "!G:G")))} -> 0 | H18: {=SUM(SUMIF(INDIRECT({"15";"16";"17";"18";"19";"20";"21"} & "!B:I"),$B18,INDIRECT({"15";"16";"17";"18";"19";"20";"21"} & "!I:I")))} -> 0 | I18: {=SUM(SUMIF(INDIRECT({"22";"23";"24";"25";"26";"27";"28";"29";"30";"31"} & "!B:G"),$B18,INDIRECT({"22";"23";"24";"25";"26";"27";"28";"29";"30";"31"} & "!G:G")))} -> 0 | J18: {=SUM(SUMIF(INDIRECT({"22";"23";"24";"25";"26";"27";"28";"29";"30";"31"} & "!B:I"),$B18,INDIRECT({"22";"23";"24";"25";"26";"27";"28";"29";"30";"31"} & "!I:I")))} -> 0 | K18: =ROUND(SUM(C18,E18,G18,I18)/DAY(TODAY()),0) -> 1 | L18: =SUM(D18,F18,H18,J18)/DAY(TODAY()) -> 20 | M18: =K18*7 -> 7 | N18: =L18*7 -> 140 | O18: =ROUND(K18*30,0) -> 30 | P18: =L18*30 -> 600 | S18: =EXACT(B18,Total!B18) -> TRUE | T18: =SUM(D18+F18+H18+J18) -> 20 | W18: BASE FIJA PARA TV 32'' - 86''
A19: U | B19: BASE GIRATORIA | C19: =SUM(SUMIF(INDIRECT({"01";"02";"03";"04";"05";"06";"07"} & "!B:G"),$B19,INDIRECT({"01";"02";"03";"04";"05";"06";"07"} & "!G:G"))) -> 0 | D19: =SUM(SUMIF(INDIRECT({"01";"02";"03";"04";"05";"06";"07"} & "!B:I"),$B19,INDIRECT({"01";"02";"03";"04";"05";"06";"07"} & "!I:I"))) -> 0 | E19: {=SUM(SUMIF(INDIRECT({"08";"09";"10";"11";"12";"13";"14"} & "!B:G"),$B19,INDIRECT({"08";"09";"10";"11";"12";"13";"14"} & "!G:G")))} -> 0 | F19: {=SUM(SUMIF(INDIRECT({"08";"09";"10";"11";"12";"13";"14"} & "!B:I"),$B19,INDIRECT({"08";"09";"10";"11";"12";"13";"14"} & "!I:I")))} -> 0 | G19: {=SUM(SUMIF(INDIRECT({"15";"16";"17";"18";"19";"20";"21"} & "!B:G"),$B19,INDIRECT({"15";"16";"17";"18";"19";"20";"21"} & "!G:G")))} -> 0 | H19: {=SUM(SUMIF(INDIRECT({"15";"16";"17";"18";"19";"20";"21"} & "!B:I"),$B19,INDIRECT({"15";"16";"17";"18";"19";"20";"21"} & "!I:I")))} -> 0 | I19: {=SUM(SUMIF(INDIRECT({"22";"23";"24";"25";"26";"27";"28";"29";"30";"31"} & "!B:G"),$B19,INDIRECT({"22";"23";"24";"25";"26";"27";"28";"29";"30";"31"} & "!G:G")))} -> 0 | J19: {=SUM(SUMIF(INDIRECT({"22";"23";"24";"25";"26";"27";"28";"29";"30";"31"} & "!B:I"),$B19,INDIRECT({"22";"23";"24";"25";"26";"27";"28";"29";"30";"31"} & "!I:I")))} -> 0 | K19: =ROUND(SUM(C19,E19,G19,I19)/DAY(TODAY()),0) -> 0 | L19: =SUM(D19,F19,H19,J19)/DAY(TODAY()) -> 0 | M19: =K19*7 -> 0 | N19: =L19*7 -> 0 | O19: =ROUND(K19*30,0) -> 0 | P19: =L19*30 -> 0 | S19: =EXACT(B19,Total!B19) -> TRUE | T19: =SUM(D19+F19+H19+J19) -> 0 | W19: BASE GIRATORIA
A20: U | B20: BASE PARA SPLIT | C20: =SUM(SUMIF(INDIRECT({"01";"02";"03";"04";"05";"06";"07"} & "!B:G"),$B20,INDIRECT({"01";"02";"03";"04";"05";"06";"07"} & "!G:G"))) -> 0 | D20: =SUM(SUMIF(INDIRECT({"01";"02";"03";"04";"05";"06";"07"} & "!B:I"),$B20,INDIRECT({"01";"02";"03";"04";"05";"06";"07"} & "!I:I"))) -> 0 | E20: {=SUM(SUMIF(INDIRECT({"08";"09";"10";"11";"12";"13";"14"} & "!B:G"),$B20,INDIRECT({"08";"09";"10";"11";"12";"13";"14"} & "!G:G")))} -> 0 | F20: {=SUM(SUMIF(INDIRECT({"08";"09";"10";"11";"12";"13";"14"} & "!B:I"),$B20,INDIRECT({"08";"09";"10";"11";"12";"13";"14"} & "!I:I")))} -> 0 | G20: {=SUM(SUMIF(INDIRECT({"15";"16";"17";"18";"19";"20";"21"} & "!B:G"),$B20,INDIRECT({"15";"16";"17";"18";"19";"20";"21"} & "!G:G")))} -> 0 | H20: {=SUM(SUMIF(INDIRECT({"15";"16";"17";"18";"19";"20";"21"} & "!B:I"),$B20,INDIRECT({"15";"16";"17";"18";"19";"20";"21"} & "!I:I")))} -> 0 | I20: {=SUM(SUMIF(INDIRECT({"22";"23";"24";"25";"26";"27";"28";"29";"30";"31"} & "!B:G"),$B20,INDIRECT({"22";"23";"24";"25";"26";"27";"28";"29";"30";"31"} & "!G:G")))} -> 0 | J20: {=SUM(SUMIF(INDIRECT({"22";"23";"24";"25";"26";"27";"28";"29";"30";"31"} & "!B:I"),$B20,INDIRECT({"22";"23";"24";"25";"26";"27";"28";"29";"30";"31"} & "!I:I")))} -> 0 | K20: =ROUND(SUM(C20,E20,G20,I20)/DAY(TODAY()),0) -> 0 | L20: =SUM(D20,F20,H20,J20)/DAY(TODAY()) -> 0 | M20: =K20*7 -> 0 | N20: =L20*7 -> 0 | O20: =ROUND(K20*30,0) -> 0 | P20: =L20*30 -> 0 | S20: =EXACT(B20,Total!B20) -> TRUE | T20: =SUM(D20+F20+H20+J20) -> 0 | W20: BASE PARA SPLIT
B21: BATERIA 15K MUST | C21: =SUM(SUMIF(INDIRECT({"01";"02";"03";"04";"05";"06";"07"} & "!B:G"),$B21,INDIRECT({"01";"02";"03";"04";"05";"06";"07"} & "!G:G"))) -> 0 | D21: =SUM(SUMIF(INDIRECT({"01";"02";"03";"04";"05";"06";"07"} & "!B:I"),$B21,INDIRECT({"01";"02";"03";"04";"05";"06";"07"} & "!I:I"))) -> 0 | E21: {=SUM(SUMIF(INDIRECT({"08";"09";"10";"11";"12";"13";"14"} & "!B:G"),$B21,INDIRECT({"08";"09";"10";"11";"12";"13";"14"} & "!G:G")))} -> 0 | F21: {=SUM(SUMIF(INDIRECT({"08";"09";"10";"11";"12";"13";"14"} & "!B:I"),$B21,INDIRECT({"08";"09";"10";"11";"12";"13";"14"} & "!I:I")))} -> 0 | G21: {=SUM(SUMIF(INDIRECT({"15";"16";"17";"18";"19";"20";"21"} & "!B:G"),$B21,INDIRECT({"15";"16";"17";"18";"19";"20";"21"} & "!G:G")))} -> 0 | H21: {=SUM(SUMIF(INDIRECT({"15";"16";"17";"18";"19";"20";"21"} & "!B:I"),$B21,INDIRECT({"15";"16";"17";"18";"19";"20";"21"} & "!I:I")))} -> 0 | I21: {=SUM(SUMIF(INDIRECT({"22";"23";"24";"25";"26";"27";"28";"29";"30";"31"} & "!B:G"),$B21,INDIRECT({"22";"23";"24";"25";"26";"27";"28";"29";"30";"31"} & "!G:G")))} -> 1 | J21: {=SUM(SUMIF(INDIRECT({"22";"23";"24";"25";"26";"27";"28";"29";"30";"31"} & "!B:I"),$B21,INDIRECT({"22";"23";"24";"25";"26";"27";"28";"29";"30";"31"} & "!I:I")))} -> 3450 | K21: =ROUND(SUM(C21,E21,G21,I21)/DAY(TODAY()),0) -> 1 | L21: =SUM(D21,F21,H21,J21)/DAY(TODAY()) -> 3450 | M21: =K21*7 -> 7 | N21: =L21*7 -> 24150 | O21: =ROUND(K21*30,0) -> 30 | P21: =L21*30 -> 103500 | S21: =EXACT(B21,Total!B21) -> TRUE | T21: =SUM(D21+F21+H21+J21) -> 3450 | W21: BATERIA 15K MUST
B22: BREKE 63A SENCILLO | C22: =SUM(SUMIF(INDIRECT({"01";"02";"03";"04";"05";"06";"07"} & "!B:G"),$B22,INDIRECT({"01";"02";"03";"04";"05";"06";"07"} & "!G:G"))) -> 0 | D22: =SUM(SUMIF(INDIRECT({"01";"02";"03";"04";"05";"06";"07"} & "!B:I"),$B22,INDIRECT({"01";"02";"03";"04";"05";"06";"07"} & "!I:I"))) -> 0 | E22: {=SUM(SUMIF(INDIRECT({"08";"09";"10";"11";"12";"13";"14"} & "!B:G"),$B22,INDIRECT({"08";"09";"10";"11";"12";"13";"14"} & "!G:G")))} -> 0 | F22: {=SUM(SUMIF(INDIRECT({"08";"09";"10";"11";"12";"13";"14"} & "!B:I"),$B22,INDIRECT({"08";"09";"10";"11";"12";"13";"14"} & "!I:I")))} -> 0 | G22: {=SUM(SUMIF(INDIRECT({"15";"16";"17";"18";"19";"20";"21"} & "!B:G"),$B22,INDIRECT({"15";"16";"17";"18";"19";"20";"21"} & "!G:G")))} -> 0 | H22: {=SUM(SUMIF(INDIRECT({"15";"16";"17";"18";"19";"20";"21"} & "!B:I"),$B22,INDIRECT({"15";"16";"17";"18";"19";"20";"21"} & "!I:I")))} -> 0 | I22: {=SUM(SUMIF(INDIRECT({"22";"23";"24";"25";"26";"27";"28";"29";"30";"31"} & "!B:G"),$B22,INDIRECT({"22";"23";"24";"25";"26";"27";"28";"29";"30";"31"} & "!G:G")))} -> 0 | J22: {=SUM(SUMIF(INDIRECT({"22";"23";"24";"25";"26";"27";"28";"29";"30";"31"} & "!B:I"),$B22,INDIRECT({"22";"23";"24";"25";"26";"27";"28";"29";"30";"31"} & "!I:I")))} -> 0 | K22: =ROUND(SUM(C22,E22,G22,I22)/DAY(TODAY()),0) -> 0 | L22: =SUM(D22,F22,H22,J22)/DAY(TODAY()) -> 0 | M22: =K22*7 -> 0 | N22: =L22*7 -> 0 | O22: =ROUND(K22*30,0) -> 0 | P22: =L22*30 -> 0 | S22: =EXACT(B22,Total!B22) -> TRUE | T22: =SUM(D22+F22+H22+J22) -> 0 | W22: BREKE 63A SENCILLO
A23: U | B23: BATERIA MUST 10.25 KW | C23: =SUM(SUMIF(INDIRECT({"01";"02";"03";"04";"05";"06";"07"} & "!B:G"),$B23,INDIRECT({"01";"02";"03";"04";"05";"06";"07"} & "!G:G"))) -> 1 | D23: =SUM(SUMIF(INDIRECT({"01";"02";"03";"04";"05";"06";"07"} & "!B:I"),$B23,INDIRECT({"01";"02";"03";"04";"05";"06";"07"} & "!I:I"))) -> 2600 | E23: {=SUM(SUMIF(INDIRECT({"08";"09";"10";"11";"12";"13";"14"} & "!B:G"),$B23,INDIRECT({"08";"09";"10";"11";"12";"13";"14"} & "!G:G")))} -> 0 | F23: {=SUM(SUMIF(INDIRECT({"08";"09";"10";"11";"12";"13";"14"} & "!B:I"),$B23,INDIRECT({"08";"09";"10";"11";"12";"13";"14"} & "!I:I")))} -> 0 | G23: {=SUM(SUMIF(INDIRECT({"15";"16";"17";"18";"19";"20";"21"} & "!B:G"),$B23,INDIRECT({"15";"16";"17";"18";"19";"20";"21"} & "!G:G")))} -> 0 | H23: {=SUM(SUMIF(INDIRECT({"15";"16";"17";"18";"19";"20";"21"} & "!B:I"),$B23,INDIRECT({"15";"16";"17";"18";"19";"20";"21"} & "!I:I")))} -> 0 | I23: {=SUM(SUMIF(INDIRECT({"22";"23";"24";"25";"26";"27";"28";"29";"30";"31"} & "!B:G"),$B23,INDIRECT({"22";"23";"24";"25";"26";"27";"28";"29";"30";"31"} & "!G:G")))} -> 0 | J23: {=SUM(SUMIF(INDIRECT({"22";"23";"24";"25";"26";"27";"28";"29";"30";"31"} & "!B:I"),$B23,INDIRECT({"22";"23";"24";"25";"26";"27";"28";"29";"30";"31"} & "!I:I")))} -> 0 | K23: =ROUND(SUM(C23,E23,G23,I23)/DAY(TODAY()),0) -> 1 | L23: =SUM(D23,F23,H23,J23)/DAY(TODAY()) -> 2600 | M23: =K23*7 -> 7 | N23: =L23*7 -> 18200 | O23: =ROUND(K23*30,0) -> 30 | P23: =L23*30 -> 78000 | S23: =EXACT(B23,Total!B23) -> TRUE | T23: =SUM(D23+F23+H23+J23) -> 2600 | W23: BATERIA MUST 10.25 KW
A24: U | B24: BREKE 63A DOBLE TIR | C24: =SUM(SUMIF(INDIRECT({"01";"02";"03";"04";"05";"06";"07"} & "!B:G"),$B24,INDIRECT({"01";"02";"03";"04";"05";"06";"07"} & "!G:G"))) -> 0 | D24: =SUM(SUMIF(INDIRECT({"01";"02";"03";"04";"05";"06";"07"} & "!B:I"),$B24,INDIRECT({"01";"02";"03";"04";"05";"06";"07"} & "!I:I"))) -> 0 | E24: {=SUM(SUMIF(INDIRECT({"08";"09";"10";"11";"12";"13";"14"} & "!B:G"),$B24,INDIRECT({"08";"09";"10";"11";"12";"13";"14"} & "!G:G")))} -> 0 | F24: {=SUM(SUMIF(INDIRECT({"08";"09";"10";"11";"12";"13";"14"} & "!B:I"),$B24,INDIRECT({"08";"09";"10";"11";"12";"13";"14"} & "!I:I")))} -> 0 | G24: {=SUM(SUMIF(INDIRECT({"15";"16";"17";"18";"19";"20";"21"} & "!B:G"),$B24,INDIRECT({"15";"16";"17";"18";"19";"20";"21"} & "!G:G")))} -> 0 | H24: {=SUM(SUMIF(INDIRECT({"15";"16";"17";"18";"19";"20";"21"} & "!B:I"),$B24,INDIRECT({"15";"16";"17";"18";"19";"20";"21"} & "!I:I")))} -> 0 | I24: {=SUM(SUMIF(INDIRECT({"22";"23";"24";"25";"26";"27";"28";"29";"30";"31"} & "!B:G"),$B24,INDIRECT({"22";"23";"24";"25";"26";"27";"28";"29";"30";"31"} & "!G:G")))} -> 0 | J24: {=SUM(SUMIF(INDIRECT({"22";"23";"24";"25";"26";"27";"28";"29";"30";"31"} & "!B:I"),$B24,INDIRECT({"22";"23";"24";"25";"26";"27";"28";"29";"30";"31"} & "!I:I")))} -> 0 | K24: =ROUND(SUM(C24,E24,G24,I24)/DAY(TODAY()),0) -> 0 | L24: =SUM(D24,F24,H24,J24)/DAY(TODAY()) -> 0 | M24: =K24*7 -> 0 | N24: =L24*7 -> 0 | O24: =ROUND(K24*30,0) -> 0 | P24: =L24*30 -> 0 | S24: =EXACT(B24,Total!B24) -> TRUE | T24: =SUM(D24+F24+H24+J24) -> 0 | W24: BREKE 63A DOBLE TIR
A25: U | B25: BREKE 32A DOBLE | C25: =SUM(SUMIF(INDIRECT({"01";"02";"03";"04";"05";"06";"07"} & "!B:G"),$B25,INDIRECT({"01";"02";"03";"04";"05";"06";"07"} & "!G:G"))) -> 0 | D25: =SUM(SUMIF(INDIRECT({"01";"02";"03";"04";"05";"06";"07"} & "!B:I"),$B25,INDIRECT({"01";"02";"03";"04";"05";"06";"07"} & "!I:I"))) -> 0 | E25: {=SUM(SUMIF(INDIRECT({"08";"09";"10";"11";"12";"13";"14"} & "!B:G"),$B25,INDIRECT({"08";"09";"10";"11";"12";"13";"14"} & "!G:G")))} -> 0 | F25: {=SUM(SUMIF(INDIRECT({"08";"09";"10";"11";"12";"13";"14"} & "!B:I"),$B25,INDIRECT({"08";"09";"10";"11";"12";"13";"14"} & "!I:I")))} -> 0 | G25: {=SUM(SUMIF(INDIRECT({"15";"16";"17";"18";"19";"20";"21"} & "!B:G"),$B25,INDIRECT({"15";"16";"17";"18";"19";"20";"21"} & "!G:G")))} -> 0 | H25: {=SUM(SUMIF(INDIRECT({"15";"16";"17";"18";"19";"20";"21"} & "!B:I"),$B25,INDIRECT({"15";"16";"17";"18";"19";"20";"21"} & "!I:I")))} -> 0 | I25: {=SUM(SUMIF(INDIRECT({"22";"23";"24";"25";"26";"27";"28";"29";"30";"31"} & "!B:G"),$B25,INDIRECT({"22";"23";"24";"25";"26";"27";"28";"29";"30";"31"} & "!G:G")))} -> 0 | J25: {=SUM(SUMIF(INDIRECT({"22";"23";"24";"25";"26";"27";"28";"29";"30";"31"} & "!B:I"),$B25,INDIRECT({"22";"23";"24";"25";"26";"27";"28";"29";"30";"31"} & "!I:I")))} -> 0 | K25: =ROUND(SUM(C25,E25,G25,I25)/DAY(TODAY()),0) -> 0 | L25: =SUM(D25,F25,H25,J25)/DAY(TODAY()) -> 0 | M25: =K25*7 -> 0 | N25: =L25*7 -> 0 | O25: =ROUND(K25*30,0) -> 0 | P25: =L25*30 -> 0 | S25: =EXACT(B25,Total!B25) -> TRUE | T25: =SUM(D25+F25+H25+J25) -> 0 | W25: BREKE 32A DOBLE
B26: BOCINA BOOM 8 PULGADAS | C26: =SUM(SUMIF(INDIRECT({"01";"02";"03";"04";"05";"06";"07"} & "!B:G"),$B26,INDIRECT({"01";"02";"03";"04";"05";"06";"07"} & "!G:G"))) -> 0 | D26: =SUM(SUMIF(INDIRECT({"01";"02";"03";"04";"05";"06";"07"} & "!B:I"),$B26,INDIRECT({"01";"02";"03";"04";"05";"06";"07"} & "!I:I"))) -> 0 | E26: {=SUM(SUMIF(INDIRECT({"08";"09";"10";"11";"12";"13";"14"} & "!B:G"),$B26,INDIRECT({"08";"09";"10";"11";"12";"13";"14"} & "!G:G")))} -> 0 | F26: {=SUM(SUMIF(INDIRECT({"08";"09";"10";"11";"12";"13";"14"} & "!B:I"),$B26,INDIRECT({"08";"09";"10";"11";"12";"13";"14"} & "!I:I")))} -> 0 | G26: {=SUM(SUMIF(INDIRECT({"15";"16";"17";"18";"19";"20";"21"} & "!B:G"),$B26,INDIRECT({"15";"16";"17";"18";"19";"20";"21"} & "!G:G")))} -> 0 | H26: {=SUM(SUMIF(INDIRECT({"15";"16";"17";"18";"19";"20";"21"} & "!B:I"),$B26,INDIRECT({"15";"16";"17";"18";"19";"20";"21"} & "!I:I")))} -> 0 | I26: {=SUM(SUMIF(INDIRECT({"22";"23";"24";"25";"26";"27";"28";"29";"30";"31"} & "!B:G"),$B26,INDIRECT({"22";"23";"24";"25";"26";"27";"28";"29";"30";"31"} & "!G:G")))} -> 0 | J26: {=SUM(SUMIF(INDIRECT({"22";"23";"24";"25";"26";"27";"28";"29";"30";"31"} & "!B:I"),$B26,INDIRECT({"22";"23";"24";"25";"26";"27";"28";"29";"30";"31"} & "!I:I")))} -> 0 | K26: =ROUND(SUM(C26,E26,G26,I26)/DAY(TODAY()),0) -> 0 | L26: =SUM(D26,F26,H26,J26)/DAY(TODAY()) -> 0 | M26: =K26*7 -> 0 | N26: =L26*7 -> 0 | O26: =ROUND(K26*30,0) -> 0 | P26: =L26*30 -> 0 | S26: =EXACT(B26,Total!B26) -> TRUE | T26: =SUM(D26+F26+H26+J26) -> 0 | W26: BOCINA BOOM 8 PULGADAS
B27: BOCINA MILEXUS 8 PULGADAS | C27: =SUM(SUMIF(INDIRECT({"01";"02";"03";"04";"05";"06";"07"} & "!B:G"),$B27,INDIRECT({"01";"02";"03";"04";"05";"06";"07"} & "!G:G"))) -> 0 | D27: =SUM(SUMIF(INDIRECT({"01";"02";"03";"04";"05";"06";"07"} & "!B:I"),$B27,INDIRECT({"01";"02";"03";"04";"05";"06";"07"} & "!I:I"))) -> 0 | E27: {=SUM(SUMIF(INDIRECT({"08";"09";"10";"11";"12";"13";"14"} & "!B:G"),$B27,INDIRECT({"08";"09";"10";"11";"12";"13";"14"} & "!G:G")))} -> 0 | F27: {=SUM(SUMIF(INDIRECT({"08";"09";"10";"11";"12";"13";"14"} & "!B:I"),$B27,INDIRECT({"08";"09";"10";"11";"12";"13";"14"} & "!I:I")))} -> 0 | G27: {=SUM(SUMIF(INDIRECT({"15";"16";"17";"18";"19";"20";"21"} & "!B:G"),$B27,INDIRECT({"15";"16";"17";"18";"19";"20";"21"} & "!G:G")))} -> 2 | H27: {=SUM(SUMIF(INDIRECT({"15";"16";"17";"18";"19";"20";"21"} & "!B:I"),$B27,INDIRECT({"15";"16";"17";"18";"19";"20";"21"} & "!I:I")))} -> 360 | I27: {=SUM(SUMIF(INDIRECT({"22";"23";"24";"25";"26";"27";"28";"29";"30";"31"} & "!B:G"),$B27,INDIRECT({"22";"23";"24";"25";"26";"27";"28";"29";"30";"31"} & "!G:G")))} -> 0 | J27: {=SUM(SUMIF(INDIRECT({"22";"23";"24";"25";"26";"27";"28";"29";"30";"31"} & "!B:I"),$B27,INDIRECT({"22";"23";"24";"25";"26";"27";"28";"29";"30";"31"} & "!I:I")))} -> 0 | K27: =ROUND(SUM(C27,E27,G27,I27)/DAY(TODAY()),0) -> 2 | L27: =SUM(D27,F27,H27,J27)/DAY(TODAY()) -> 360 | M27: =K27*7 -> 14 | N27: =L27*7 -> 2520 | O27: =ROUND(K27*30,0) -> 60 | P27: =L27*30 -> 10800 | S27: =EXACT(B27,Total!B27) -> TRUE | T27: =SUM(D27+F27+H27+J27) -> 360 | W27: BOCINA MILEXUS 8 PULGADAS
B28: BOCINA MILEXUS 6 DUAL | C28: =SUM(SUMIF(INDIRECT({"01";"02";"03";"04";"05";"06";"07"} & "!B:G"),$B28,INDIRECT({"01";"02";"03";"04";"05";"06";"07"} & "!G:G"))) -> 0 | D28: =SUM(SUMIF(INDIRECT({"01";"02";"03";"04";"05";"06";"07"} & "!B:I"),$B28,INDIRECT({"01";"02";"03";"04";"05";"06";"07"} & "!I:I"))) -> 0 | E28: {=SUM(SUMIF(INDIRECT({"08";"09";"10";"11";"12";"13";"14"} & "!B:G"),$B28,INDIRECT({"08";"09";"10";"11";"12";"13";"14"} & "!G:G")))} -> 0 | F28: {=SUM(SUMIF(INDIRECT({"08";"09";"10";"11";"12";"13";"14"} & "!B:I"),$B28,INDIRECT({"08";"09";"10";"11";"12";"13";"14"} & "!I:I")))} -> 0 | G28: {=SUM(SUMIF(INDIRECT({"15";"16";"17";"18";"19";"20";"21"} & "!B:G"),$B28,INDIRECT({"15";"16";"17";"18";"19";"20";"21"} & "!G:G")))} -> 0 | H28: {=SUM(SUMIF(INDIRECT({"15";"16";"17";"18";"19";"20";"21"} & "!B:I"),$B28,INDIRECT({"15";"16";"17";"18";"19";"20";"21"} & "!I:I")))} -> 0 | I28: {=SUM(SUMIF(INDIRECT({"22";"23";"24";"25";"26";"27";"28";"29";"30";"31"} & "!B:G"),$B28,INDIRECT({"22";"23";"24";"25";"26";"27";"28";"29";"30";"31"} & "!G:G")))} -> 0 | J28: {=SUM(SUMIF(INDIRECT({"22";"23";"24";"25";"26";"27";"28";"29";"30";"31"} & "!B:I"),$B28,INDIRECT({"22";"23";"24";"25";"26";"27";"28";"29";"30";"31"} & "!I:I")))} -> 0 | K28: =ROUND(SUM(C28,E28,G28,I28)/DAY(TODAY()),0) -> 0 | L28: =SUM(D28,F28,H28,J28)/DAY(TODAY()) -> 0 | M28: =K28*7 -> 0 | N28: =L28*7 -> 0 | O28: =ROUND(K28*30,0) -> 0 | P28: =L28*30 -> 0 | S28: =EXACT(B28,Total!B28) -> TRUE | T28: =SUM(D28+F28+H28+J28) -> 0 | W28: BOCINA MILEXUS 6 DUAL
A29: U | B29: BOMBA DE AGUA SILVER POINT 1 HP | C29: =SUM(SUMIF(INDIRECT({"01";"02";"03";"04";"05";"06";"07"} & "!B:G"),$B29,INDIRECT({"01";"02";"03";"04";"05";"06";"07"} & "!G:G"))) -> 0 | D29: =SUM(SUMIF(INDIRECT({"01";"02";"03";"04";"05";"06";"07"} & "!B:I"),$B29,INDIRECT({"01";"02";"03";"04";"05";"06";"07"} & "!I:I"))) -> 0 | E29: {=SUM(SUMIF(INDIRECT({"08";"09";"10";"11";"12";"13";"14"} & "!B:G"),$B29,INDIRECT({"08";"09";"10";"11";"12";"13";"14"} & "!G:G")))} -> 0 | F29: {=SUM(SUMIF(INDIRECT({"08";"09";"10";"11";"12";"13";"14"} & "!B:I"),$B29,INDIRECT({"08";"09";"10";"11";"12";"13";"14"} & "!I:I")))} -> 0 | G29: {=SUM(SUMIF(INDIRECT({"15";"16";"17";"18";"19";"20";"21"} & "!B:G"),$B29,INDIRECT({"15";"16";"17";"18";"19";"20";"21"} & "!G:G")))} -> 0 | H29: {=SUM(SUMIF(INDIRECT({"15";"16";"17";"18";"19";"20";"21"} & "!B:I"),$B29,INDIRECT({"15";"16";"17";"18";"19";"20";"21"} & "!I:I")))} -> 0 | I29: {=SUM(SUMIF(INDIRECT({"22";"23";"24";"25";"26";"27";"28";"29";"30";"31"} & "!B:G"),$B29,INDIRECT({"22";"23";"24";"25";"26";"27";"28";"29";"30";"31"} & "!G:G")))} -> 0 | J29: {=SUM(SUMIF(INDIRECT({"22";"23";"24";"25";"26";"27";"28";"29";"30";"31"} & "!B:I"),$B29,INDIRECT({"22";"23";"24";"25";"26";"27";"28";"29";"30";"31"} & "!I:I")))} -> 0 | K29: =ROUND(SUM(C29,E29,G29,I29)/DAY(TODAY()),0) -> 0 | L29: =SUM(D29,F29,H29,J29)/DAY(TODAY()) -> 0 | M29: =K29*7 -> 0 | N29: =L29*7 -> 0 | O29: =ROUND(K29*30,0) -> 0 | P29: =L29*30 -> 0 | S29: =EXACT(B29,Total!B29) -> TRUE | T29: =SUM(D29+F29+H29+J29) -> 0 | W29: BOMBA DE AGUA SILVER POINT 1 HP
B30: BOMBA DE AGUA SILVER POINT 1X1/2 | C30: =SUM(SUMIF(INDIRECT({"01";"02";"03";"04";"05";"06";"07"} & "!B:G"),$B30,INDIRECT({"01";"02";"03";"04";"05";"06";"07"} & "!G:G"))) -> 0 | D30: =SUM(SUMIF(INDIRECT({"01";"02";"03";"04";"05";"06";"07"} & "!B:I"),$B30,INDIRECT({"01";"02";"03";"04";"05";"06";"07"} & "!I:I"))) -> 0 | E30: {=SUM(SUMIF(INDIRECT({"08";"09";"10";"11";"12";"13";"14"} & "!B:G"),$B30,INDIRECT({"08";"09";"10";"11";"12";"13";"14"} & "!G:G")))} -> 0 | F30: {=SUM(SUMIF(INDIRECT({"08";"09";"10";"11";"12";"13";"14"} & "!B:I"),$B30,INDIRECT({"08";"09";"10";"11";"12";"13";"14"} & "!I:I")))} -> 0 | G30: {=SUM(SUMIF(INDIRECT({"15";"16";"17";"18";"19";"20";"21"} & "!B:G"),$B30,INDIRECT({"15";"16";"17";"18";"19";"20";"21"} & "!G:G")))} -> 0 | H30: {=SUM(SUMIF(INDIRECT({"15";"16";"17";"18";"19";"20";"21"} & "!B:I"),$B30,INDIRECT({"15";"16";"17";"18";"19";"20";"21"} & "!I:I")))} -> 0 | I30: {=SUM(SUMIF(INDIRECT({"22";"23";"24";"25";"26";"27";"28";"29";"30";"31"} & "!B:G"),$B30,INDIRECT({"22";"23";"24";"25";"26";"27";"28";"29";"30";"31"} & "!G:G")))} -> 1 | J30: {=SUM(SUMIF(INDIRECT({"22";"23";"24";"25";"26";"27";"28";"29";"30";"31"} & "!B:I"),$B30,INDIRECT({"22";"23";"24";"25";"26";"27";"28";"29";"30";"31"} & "!I:I")))} -> 45 | K30: =ROUND(SUM(C30,E30,G30,I30)/DAY(TODAY()),0) -> 1 | L30: =SUM(D30,F30,H30,J30)/DAY(TODAY()) -> 45 | M30: =K30*7 -> 7 | N30: =L30*7 -> 315 | O30: =ROUND(K30*30,0) -> 30 | P30: =L30*30 -> 1350 | S30: =EXACT(B30,Total!B30) -> TRUE | T30: =SUM(D30+F30+H30+J30) -> 45 | W30: BOMBA DE AGUA SILVER POINT 1X1/2
B31: BICICLETA INFANTIL | C31: =SUM(SUMIF(INDIRECT({"01";"02";"03";"04";"05";"06";"07"} & "!B:G"),$B31,INDIRECT({"01";"02";"03";"04";"05";"06";"07"} & "!G:G"))) -> 0 | D31: =SUM(SUMIF(INDIRECT({"01";"02";"03";"04";"05";"06";"07"} & "!B:I"),$B31,INDIRECT({"01";"02";"03";"04";"05";"06";"07"} & "!I:I"))) -> 0 | E31: {=SUM(SUMIF(INDIRECT({"08";"09";"10";"11";"12";"13";"14"} & "!B:G"),$B31,INDIRECT({"08";"09";"10";"11";"12";"13";"14"} & "!G:G")))} -> 0 | F31: {=SUM(SUMIF(INDIRECT({"08";"09";"10";"11";"12";"13";"14"} & "!B:I"),$B31,INDIRECT({"08";"09";"10";"11";"12";"13";"14"} & "!I:I")))} -> 0 | G31: {=SUM(SUMIF(INDIRECT({"15";"16";"17";"18";"19";"20";"21"} & "!B:G"),$B31,INDIRECT({"15";"16";"17";"18";"19";"20";"21"} & "!G:G")))} -> 0 | H31: {=SUM(SUMIF(INDIRECT({"15";"16";"17";"18";"19";"20";"21"} & "!B:I"),$B31,INDIRECT({"15";"16";"17";"18";"19";"20";"21"} & "!I:I")))} -> 0 | I31: {=SUM(SUMIF(INDIRECT({"22";"23";"24";"25";"26";"27";"28";"29";"30";"31"} & "!B:G"),$B31,INDIRECT({"22";"23";"24";"25";"26";"27";"28";"29";"30";"31"} & "!G:G")))} -> 0 | J31: {=SUM(SUMIF(INDIRECT({"22";"23";"24";"25";"26";"27";"28";"29";"30";"31"} & "!B:I"),$B31,INDIRECT({"22";"23";"24";"25";"26";"27";"28";"29";"30";"31"} & "!I:I")))} -> 0 | K31: =ROUND(SUM(C31,E31,G31,I31)/DAY(TODAY()),0) -> 0 | L31: =SUM(D31,F31,H31,J31)/DAY(TODAY()) -> 0 | M31: =K31*7 -> 0 | N31: =L31*7 -> 0 | O31: =ROUND(K31*30,0) -> 0 | P31: =L31*30 -> 0 | S31: =EXACT(B31,Total!B31) -> TRUE | T31: =SUM(D31+F31+H31+J31) -> 0 | W31: BICICLETA INFANTIL
B32: BICICLETA INFANTIL 20 TZ002 | C32: =SUM(SUMIF(INDIRECT({"01";"02";"03";"04";"05";"06";"07"} & "!B:G"),$B32,INDIRECT({"01";"02";"03";"04";"05";"06";"07"} & "!G:G"))) -> 1 | D32: =SUM(SUMIF(INDIRECT({"01";"02";"03";"04";"05";"06";"07"} & "!B:I"),$B32,INDIRECT({"01";"02";"03";"04";"05";"06";"07"} & "!I:I"))) -> 130 | E32: {=SUM(SUMIF(INDIRECT({"08";"09";"10";"11";"12";"13";"14"} & "!B:G"),$B32,INDIRECT({"08";"09";"10";"11";"12";"13";"14"} & "!G:G")))} -> 0 | F32: {=SUM(SUMIF(INDIRECT({"08";"09";"10";"11";"12";"13";"14"} & "!B:I"),$B32,INDIRECT({"08";"09";"10";"11";"12";"13";"14"} & "!I:I")))} -> 0 | G32: {=SUM(SUMIF(INDIRECT({"15";"16";"17";"18";"19";"20";"21"} & "!B:G"),$B32,INDIRECT({"15";"16";"17";"18";"19";"20";"21"} & "!G:G")))} -> 0 | H32: {=SUM(SUMIF(INDIRECT({"15";"16";"17";"18";"19";"20";"21"} & "!B:I"),$B32,INDIRECT({"15";"16";"17";"18";"19";"20";"21"} & "!I:I")))} -> 0 | I32: {=SUM(SUMIF(INDIRECT({"22";"23";"24";"25";"26";"27";"28";"29";"30";"31"} & "!B:G"),$B32,INDIRECT({"22";"23";"24";"25";"26";"27";"28";"29";"30";"31"} & "!G:G")))} -> 0 | J32: {=SUM(SUMIF(INDIRECT({"22";"23";"24";"25";"26";"27";"28";"29";"30";"31"} & "!B:I"),$B32,INDIRECT({"22";"23";"24";"25";"26";"27";"28";"29";"30";"31"} & "!I:I")))} -> 0 | K32: =ROUND(SUM(C32,E32,G32,I32)/DAY(TODAY()),0) -> 1 | L32: =SUM(D32,F32,H32,J32)/DAY(TODAY()) -> 130 | M32: =K32*7 -> 7 | N32: =L32*7 -> 910 | O32: =ROUND(K32*30,0) -> 30 | P32: =L32*30 -> 3900 | S32: =EXACT(B32,Total!B32) -> TRUE | T32: =SUM(D32+F32+H32+J32) -> 130 | W32: BICICLETA INFANTIL 20 TZ002
A33: U | B33: BICICLETA 26 008-5 | C33: =SUM(SUMIF(INDIRECT({"01";"02";"03";"04";"05";"06";"07"} & "!B:G"),$B33,INDIRECT({"01";"02";"03";"04";"05";"06";"07"} & "!G:G"))) -> 0 | D33: =SUM(SUMIF(INDIRECT({"01";"02";"03";"04";"05";"06";"07"} & "!B:I"),$B33,INDIRECT({"01";"02";"03";"04";"05";"06";"07"} & "!I:I"))) -> 0 | E33: {=SUM(SUMIF(INDIRECT({"08";"09";"10";"11";"12";"13";"14"} & "!B:G"),$B33,INDIRECT({"08";"09";"10";"11";"12";"13";"14"} & "!G:G")))} -> 0 | F33: {=SUM(SUMIF(INDIRECT({"08";"09";"10";"11";"12";"13";"14"} & "!B:I"),$B33,INDIRECT({"08";"09";"10";"11";"12";"13";"14"} & "!I:I")))} -> 0 | G33: {=SUM(SUMIF(INDIRECT({"15";"16";"17";"18";"19";"20";"21"} & "!B:G"),$B33,INDIRECT({"15";"16";"17";"18";"19";"20";"21"} & "!G:G")))} -> 0 | H33: {=SUM(SUMIF(INDIRECT({"15";"16";"17";"18";"19";"20";"21"} & "!B:I"),$B33,INDIRECT({"15";"16";"17";"18";"19";"20";"21"} & "!I:I")))} -> 0 | I33: {=SUM(SUMIF(INDIRECT({"22";"23";"24";"25";"26";"27";"28";"29";"30";"31"} & "!B:G"),$B33,INDIRECT({"22";"23";"24";"25";"26";"27";"28";"29";"30";"31"} & "!G:G")))} -> 0 | J33: {=SUM(SUMIF(INDIRECT({"22";"23";"24";"25";"26";"27";"28";"29";"30";"31"} & "!B:I"),$B33,INDIRECT({"22";"23";"24";"25";"26";"27";"28";"29";"30";"31"} & "!I:I")))} -> 0 | K33: =ROUND(SUM(C33,E33,G33,I33)/DAY(TODAY()),0) -> 0 | L33: =SUM(D33,F33,H33,J33)/DAY(TODAY()) -> 0 | M33: =K33*7 -> 0 | N33: =L33*7 -> 0 | O33: =ROUND(K33*30,0) -> 0 | P33: =L33*30 -> 0 | S33: =EXACT(B33,Total!B33) -> TRUE | T33: =SUM(D33+F33+H33+J33) -> 0 | W33: BICICLETA 26 008-5
A34: U | B34: BICICLETA 26 012 | C34: =SUM(SUMIF(INDIRECT({"01";"02";"03";"04";"05";"06";"07"} & "!B:G"),$B34,INDIRECT({"01";"02";"03";"04";"05";"06";"07"} & "!G:G"))) -> 0 | D34: =SUM(SUMIF(INDIRECT({"01";"02";"03";"04";"05";"06";"07"} & "!B:I"),$B34,INDIRECT({"01";"02";"03";"04";"05";"06";"07"} & "!I:I"))) -> 0 | E34: {=SUM(SUMIF(INDIRECT({"08";"09";"10";"11";"12";"13";"14"} & "!B:G"),$B34,INDIRECT({"08";"09";"10";"11";"12";"13";"14"} & "!G:G")))} -> 0 | F34: {=SUM(SUMIF(INDIRECT({"08";"09";"10";"11";"12";"13";"14"} & "!B:I"),$B34,INDIRECT({"08";"09";"10";"11";"12";"13";"14"} & "!I:I")))} -> 0 | G34: {=SUM(SUMIF(INDIRECT({"15";"16";"17";"18";"19";"20";"21"} & "!B:G"),$B34,INDIRECT({"15";"16";"17";"18";"19";"20";"21"} & "!G:G")))} -> 0 | H34: {=SUM(SUMIF(INDIRECT({"15";"16";"17";"18";"19";"20";"21"} & "!B:I"),$B34,INDIRECT({"15";"16";"17";"18";"19";"20";"21"} & "!I:I")))} -> 0 | I34: {=SUM(SUMIF(INDIRECT({"22";"23";"24";"25";"26";"27";"28";"29";"30";"31"} & "!B:G"),$B34,INDIRECT({"22";"23";"24";"25";"26";"27";"28";"29";"30";"31"} & "!G:G")))} -> 0 | J34: {=SUM(SUMIF(INDIRECT({"22";"23";"24";"25";"26";"27";"28";"29";"30";"31"} & "!B:I"),$B34,INDIRECT({"22";"23";"24";"25";"26";"27";"28";"29";"30";"31"} & "!I:I")))} -> 0 | K34: =ROUND(SUM(C34,E34,G34,I34)/DAY(TODAY()),0) -> 0 | L34: =SUM(D34,F34,H34,J34)/DAY(TODAY()) -> 0 | M34: =K34*7 -> 0 | N34: =L34*7 -> 0 | O34: =ROUND(K34*30,0) -> 0 | P34: =L34*30 -> 0 | S34: =EXACT(B34,Total!B34) -> TRUE | T34: =SUM(D34+F34+H34+J34) -> 0 | W34: BICICLETA 26 012
A35: U | B35: BICICLETA 26 003-4 | C35: =SUM(SUMIF(INDIRECT({"01";"02";"03";"04";"05";"06";"07"} & "!B:G"),$B35,INDIRECT({"01";"02";"03";"04";"05";"06";"07"} & "!G:G"))) -> 0 | D35: =SUM(SUMIF(INDIRECT({"01";"02";"03";"04";"05";"06";"07"} & "!B:I"),$B35,INDIRECT({"01";"02";"03";"04";"05";"06";"07"} & "!I:I"))) -> 0 | E35: {=SUM(SUMIF(INDIRECT({"08";"09";"10";"11";"12";"13";"14"} & "!B:G"),$B35,INDIRECT({"08";"09";"10";"11";"12";"13";"14"} & "!G:G")))} -> 1 | F35: {=SUM(SUMIF(INDIRECT({"08";"09";"10";"11";"12";"13";"14"} & "!B:I"),$B35,INDIRECT({"08";"09";"10";"11";"12";"13";"14"} & "!I:I")))} -> 185 | G35: {=SUM(SUMIF(INDIRECT({"15";"16";"17";"18";"19";"20";"21"} & "!B:G"),$B35,INDIRECT({"15";"16";"17";"18";"19";"20";"21"} & "!G:G")))} -> 0 | H35: {=SUM(SUMIF(INDIRECT({"15";"16";"17";"18";"19";"20";"21"} & "!B:I"),$B35,INDIRECT({"15";"16";"17";"18";"19";"20";"21"} & "!I:I")))} -> 0 | I35: {=SUM(SUMIF(INDIRECT({"22";"23";"24";"25";"26";"27";"28";"29";"30";"31"} & "!B:G"),$B35,INDIRECT({"22";"23";"24";"25";"26";"27";"28";"29";"30";"31"} & "!G:G")))} -> 0 | J35: {=SUM(SUMIF(INDIRECT({"22";"23";"24";"25";"26";"27";"28";"29";"30";"31"} & "!B:I"),$B35,INDIRECT({"22";"23";"24";"25";"26";"27";"28";"29";"30";"31"} & "!I:I")))} -> 0 | K35: =ROUND(SUM(C35,E35,G35,I35)/DAY(TODAY()),0) -> 1 | L35: =SUM(D35,F35,H35,J35)/DAY(TODAY()) -> 185 | M35: =K35*7 -> 7 | N35: =L35*7 -> 1295 | O35: =ROUND(K35*30,0) -> 30 | P35: =L35*30 -> 5550 | S35: =EXACT(B35,Total!B35) -> TRUE | T35: =SUM(D35+F35+H35+J35) -> 185 | W35: BICICLETA 26 003-4
A36: U | B36: BICICLETA 16 023 | C36: =SUM(SUMIF(INDIRECT({"01";"02";"03";"04";"05";"06";"07"} & "!B:G"),$B36,INDIRECT({"01";"02";"03";"04";"05";"06";"07"} & "!G:G"))) -> 0 | D36: =SUM(SUMIF(INDIRECT({"01";"02";"03";"04";"05";"06";"07"} & "!B:I"),$B36,INDIRECT({"01";"02";"03";"04";"05";"06";"07"} & "!I:I"))) -> 0 | E36: {=SUM(SUMIF(INDIRECT({"08";"09";"10";"11";"12";"13";"14"} & "!B:G"),$B36,INDIRECT({"08";"09";"10";"11";"12";"13";"14"} & "!G:G")))} -> 0 | F36: {=SUM(SUMIF(INDIRECT({"08";"09";"10";"11";"12";"13";"14"} & "!B:I"),$B36,INDIRECT({"08";"09";"10";"11";"12";"13";"14"} & "!I:I")))} -> 0 | G36: {=SUM(SUMIF(INDIRECT({"15";"16";"17";"18";"19";"20";"21"} & "!B:G"),$B36,INDIRECT({"15";"16";"17";"18";"19";"20";"21"} & "!G:G")))} -> 0 | H36: {=SUM(SUMIF(INDIRECT({"15";"16";"17";"18";"19";"20";"21"} & "!B:I"),$B36,INDIRECT({"15";"16";"17";"18";"19";"20";"21"} & "!I:I")))} -> 0 | I36: {=SUM(SUMIF(INDIRECT({"22";"23";"24";"25";"26";"27";"28";"29";"30";"31"} & "!B:G"),$B36,INDIRECT({"22";"23";"24";"25";"26";"27";"28";"29";"30";"31"} & "!G:G")))} -> 0 | J36: {=SUM(SUMIF(INDIRECT({"22";"23";"24";"25";"26";"27";"28";"29";"30";"31"} & "!B:I"),$B36,INDIRECT({"22";"23";"24";"25";"26";"27";"28";"29";"30";"31"} & "!I:I")))} -> 0 | K36: =ROUND(SUM(C36,E36,G36,I36)/DAY(TODAY()),0) -> 0 | L36: =SUM(D36,F36,H36,J36)/DAY(TODAY()) -> 0 | M36: =K36*7 -> 0 | N36: =L36*7 -> 0 | O36: =ROUND(K36*30,0) -> 0 | P36: =L36*30 -> 0 | S36: =EXACT(B36,Total!B36) -> TRUE | T36: =SUM(D36+F36+H36+J36) -> 0 | W36: BICICLETA 16 023
A37: U | B37: BICICLETA ELECTRICA | C37: =SUM(SUMIF(INDIRECT({"01";"02";"03";"04";"05";"06";"07"} & "!B:G"),$B37,INDIRECT({"01";"02";"03";"04";"05";"06";"07"} & "!G:G"))) -> 0 | D37: =SUM(SUMIF(INDIRECT({"01";"02";"03";"04";"05";"06";"07"} & "!B:I"),$B37,INDIRECT({"01";"02";"03";"04";"05";"06";"07"} & "!I:I"))) -> 0 | E37: {=SUM(SUMIF(INDIRECT({"08";"09";"10";"11";"12";"13";"14"} & "!B:G"),$B37,INDIRECT({"08";"09";"10";"11";"12";"13";"14"} & "!G:G")))} -> 0 | F37: {=SUM(SUMIF(INDIRECT({"08";"09";"10";"11";"12";"13";"14"} & "!B:I"),$B37,INDIRECT({"08";"09";"10";"11";"12";"13";"14"} & "!I:I")))} -> 0 | G37: {=SUM(SUMIF(INDIRECT({"15";"16";"17";"18";"19";"20";"21"} & "!B:G"),$B37,INDIRECT({"15";"16";"17";"18";"19";"20";"21"} & "!G:G")))} -> 0 | H37: {=SUM(SUMIF(INDIRECT({"15";"16";"17";"18";"19";"20";"21"} & "!B:I"),$B37,INDIRECT({"15";"16";"17";"18";"19";"20";"21"} & "!I:I")))} -> 0 | I37: {=SUM(SUMIF(INDIRECT({"22";"23";"24";"25";"26";"27";"28";"29";"30";"31"} & "!B:G"),$B37,INDIRECT({"22";"23";"24";"25";"26";"27";"28";"29";"30";"31"} & "!G:G")))} -> 0 | J37: {=SUM(SUMIF(INDIRECT({"22";"23";"24";"25";"26";"27";"28";"29";"30";"31"} & "!B:I"),$B37,INDIRECT({"22";"23";"24";"25";"26";"27";"28";"29";"30";"31"} & "!I:I")))} -> 0 | K37: =ROUND(SUM(C37,E37,G37,I37)/DAY(TODAY()),0) -> 0 | L37: =SUM(D37,F37,H37,J37)/DAY(TODAY()) -> 0 | M37: =K37*7 -> 0 | N37: =L37*7 -> 0 | O37: =ROUND(K37*30,0) -> 0 | P37: =L37*30 -> 0 | S37: =EXACT(B37,Total!B37) -> TRUE | T37: =SUM(D37+F37+H37+J37) -> 0 | W37: BICICLETA ELECTRICA
B38: CONECTORES MC4 | C38: =SUM(SUMIF(INDIRECT({"01";"02";"03";"04";"05";"06";"07"} & "!B:G"),$B38,INDIRECT({"01";"02";"03";"04";"05";"06";"07"} & "!G:G"))) -> 0 | D38: =SUM(SUMIF(INDIRECT({"01";"02";"03";"04";"05";"06";"07"} & "!B:I"),$B38,INDIRECT({"01";"02";"03";"04";"05";"06";"07"} & "!I:I"))) -> 0 | E38: {=SUM(SUMIF(INDIRECT({"08";"09";"10";"11";"12";"13";"14"} & "!B:G"),$B38,INDIRECT({"08";"09";"10";"11";"12";"13";"14"} & "!G:G")))} -> 0 | F38: {=SUM(SUMIF(INDIRECT({"08";"09";"10";"11";"12";"13";"14"} & "!B:I"),$B38,INDIRECT({"08";"09";"10";"11";"12";"13";"14"} & "!I:I")))} -> 0 | G38: {=SUM(SUMIF(INDIRECT({"15";"16";"17";"18";"19";"20";"21"} & "!B:G"),$B38,INDIRECT({"15";"16";"17";"18";"19";"20";"21"} & "!G:G")))} -> 0 | H38: {=SUM(SUMIF(INDIRECT({"15";"16";"17";"18";"19";"20";"21"} & "!B:I"),$B38,INDIRECT({"15";"16";"17";"18";"19";"20";"21"} & "!I:I")))} -> 0 | I38: {=SUM(SUMIF(INDIRECT({"22";"23";"24";"25";"26";"27";"28";"29";"30";"31"} & "!B:G"),$B38,INDIRECT({"22";"23";"24";"25";"26";"27";"28";"29";"30";"31"} & "!G:G")))} -> 0 | J38: {=SUM(SUMIF(INDIRECT({"22";"23";"24";"25";"26";"27";"28";"29";"30";"31"} & "!B:I"),$B38,INDIRECT({"22";"23";"24";"25";"26";"27";"28";"29";"30";"31"} & "!I:I")))} -> 0 | K38: =ROUND(SUM(C38,E38,G38,I38)/DAY(TODAY()),0) -> 0 | L38: =SUM(D38,F38,H38,J38)/DAY(TODAY()) -> 0 | M38: =K38*7 -> 0 | N38: =L38*7 -> 0 | O38: =ROUND(K38*30,0) -> 0 | P38: =L38*30 -> 0 | S38: =EXACT(B38,Total!B38) -> TRUE | T38: =SUM(D38+F38+H38+J38) -> 0 | W38: CONECTORES MC4
A39: U | B39: CAJITA DECODIFICADORA ATEC | C39: =SUM(SUMIF(INDIRECT({"01";"02";"03";"04";"05";"06";"07"} & "!B:G"),$B39,INDIRECT({"01";"02";"03";"04";"05";"06";"07"} & "!G:G"))) -> 0 | D39: =SUM(SUMIF(INDIRECT({"01";"02";"03";"04";"05";"06";"07"} & "!B:I"),$B39,INDIRECT({"01";"02";"03";"04";"05";"06";"07"} & "!I:I"))) -> 0 | E39: {=SUM(SUMIF(INDIRECT({"08";"09";"10";"11";"12";"13";"14"} & "!B:G"),$B39,INDIRECT({"08";"09";"10";"11";"12";"13";"14"} & "!G:G")))} -> 1 | F39: {=SUM(SUMIF(INDIRECT({"08";"09";"10";"11";"12";"13";"14"} & "!B:I"),$B39,INDIRECT({"08";"09";"10";"11";"12";"13";"14"} & "!I:I")))} -> 15 | G39: {=SUM(SUMIF(INDIRECT({"15";"16";"17";"18";"19";"20";"21"} & "!B:G"),$B39,INDIRECT({"15";"16";"17";"18";"19";"20";"21"} & "!G:G")))} -> 3 | H39: {=SUM(SUMIF(INDIRECT({"15";"16";"17";"18";"19";"20";"21"} & "!B:I"),$B39,INDIRECT({"15";"16";"17";"18";"19";"20";"21"} & "!I:I")))} -> 135 | I39: {=SUM(SUMIF(INDIRECT({"22";"23";"24";"25";"26";"27";"28";"29";"30";"31"} & "!B:G"),$B39,INDIRECT({"22";"23";"24";"25";"26";"27";"28";"29";"30";"31"} & "!G:G")))} -> 0 | J39: {=SUM(SUMIF(INDIRECT({"22";"23";"24";"25";"26";"27";"28";"29";"30";"31"} & "!B:I"),$B39,INDIRECT({"22";"23";"24";"25";"26";"27";"28";"29";"30";"31"} & "!I:I")))} -> 0 | K39: =ROUND(SUM(C39,E39,G39,I39)/DAY(TODAY()),0) -> 4 | L39: =SUM(D39,F39,H39,J39)/DAY(TODAY()) -> 150 | M39: =K39*7 -> 28 | N39: =L39*7 -> 1050 | O39: =ROUND(K39*30,0) -> 120 | P39: =L39*30 -> 4500 | S39: =EXACT(B39,Total!B39) -> TRUE | T39: =SUM(D39+F39+H39+J39) -> 150 | W39: CAJITA DECODIFICADORA ATEC
A40: U | B40: CAJA DE DISTRIBUCION DE 8 VIAS | C40: =SUM(SUMIF(INDIRECT({"01";"02";"03";"04";"05";"06";"07"} & "!B:G"),$B40,INDIRECT({"01";"02";"03";"04";"05";"06";"07"} & "!G:G"))) -> 0 | D40: =SUM(SUMIF(INDIRECT({"01";"02";"03";"04";"05";"06";"07"} & "!B:I"),$B40,INDIRECT({"01";"02";"03";"04";"05";"06";"07"} & "!I:I"))) -> 0 | E40: {=SUM(SUMIF(INDIRECT({"08";"09";"10";"11";"12";"13";"14"} & "!B:G"),$B40,INDIRECT({"08";"09";"10";"11";"12";"13";"14"} & "!G:G")))} -> 0 | F40: {=SUM(SUMIF(INDIRECT({"08";"09";"10";"11";"12";"13";"14"} & "!B:I"),$B40,INDIRECT({"08";"09";"10";"11";"12";"13";"14"} & "!I:I")))} -> 0 | G40: {=SUM(SUMIF(INDIRECT({"15";"16";"17";"18";"19";"20";"21"} & "!B:G"),$B40,INDIRECT({"15";"16";"17";"18";"19";"20";"21"} & "!G:G")))} -> 0 | H40: {=SUM(SUMIF(INDIRECT({"15";"16";"17";"18";"19";"20";"21"} & "!B:I"),$B40,INDIRECT({"15";"16";"17";"18";"19";"20";"21"} & "!I:I")))} -> 0 | I40: {=SUM(SUMIF(INDIRECT({"22";"23";"24";"25";"26";"27";"28";"29";"30";"31"} & "!B:G"),$B40,INDIRECT({"22";"23";"24";"25";"26";"27";"28";"29";"30";"31"} & "!G:G")))} -> 0 | J40: {=SUM(SUMIF(INDIRECT({"22";"23";"24";"25";"26";"27";"28";"29";"30";"31"} & "!B:I"),$B40,INDIRECT({"22";"23";"24";"25";"26";"27";"28";"29";"30";"31"} & "!I:I")))} -> 0 | K40: =ROUND(SUM(C40,E40,G40,I40)/DAY(TODAY()),0) -> 0 | L40: =SUM(D40,F40,H40,J40)/DAY(TODAY()) -> 0 | M40: =K40*7 -> 0 | N40: =L40*7 -> 0 | O40: =ROUND(K40*30,0) -> 0 | P40: =L40*30 -> 0 | S40: =EXACT(B40,Total!B40) -> TRUE | T40: =SUM(D40+F40+H40+J40) -> 0 | W40: CAJA DE DISTRIBUCION DE 8 VIAS
A41: U | B41: CAJA DE DISTRIBUCION DE 12 VIAS | C41: =SUM(SUMIF(INDIRECT({"01";"02";"03";"04";"05";"06";"07"} & "!B:G"),$B41,INDIRECT({"01";"02";"03";"04";"05";"06";"07"} & "!G:G"))) -> 0 | D41: =SUM(SUMIF(INDIRECT({"01";"02";"03";"04";"05";"06";"07"} & "!B:I"),$B41,INDIRECT({"01";"02";"03";"04";"05";"06";"07"} & "!I:I"))) -> 0 | E41: {=SUM(SUMIF(INDIRECT({"08";"09";"10";"11";"12";"13";"14"} & "!B:G"),$B41,INDIRECT({"08";"09";"10";"11";"12";"13";"14"} & "!G:G")))} -> 0 | F41: {=SUM(SUMIF(INDIRECT({"08";"09";"10";"11";"12";"13";"14"} & "!B:I"),$B41,INDIRECT({"08";"09";"10";"11";"12";"13";"14"} & "!I:I")))} -> 0 | G41: {=SUM(SUMIF(INDIRECT({"15";"16";"17";"18";"19";"20";"21"} & "!B:G"),$B41,INDIRECT({"15";"16";"17";"18";"19";"20";"21"} & "!G:G")))} -> 0 | H41: {=SUM(SUMIF(INDIRECT({"15";"16";"17";"18";"19";"20";"21"} & "!B:I"),$B41,INDIRECT({"15";"16";"17";"18";"19";"20";"21"} & "!I:I")))} -> 0 | I41: {=SUM(SUMIF(INDIRECT({"22";"23";"24";"25";"26";"27";"28";"29";"30";"31"} & "!B:G"),$B41,INDIRECT({"22";"23";"24";"25";"26";"27";"28";"29";"30";"31"} & "!G:G")))} -> 0 | J41: {=SUM(SUMIF(INDIRECT({"22";"23";"24";"25";"26";"27";"28";"29";"30";"31"} & "!B:I"),$B41,INDIRECT({"22";"23";"24";"25";"26";"27";"28";"29";"30";"31"} & "!I:I")))} -> 0 | K41: =ROUND(SUM(C41,E41,G41,I41)/DAY(TODAY()),0) -> 0 | L41: =SUM(D41,F41,H41,J41)/DAY(TODAY()) -> 0 | M41: =K41*7 -> 0 | N41: =L41*7 -> 0 | O41: =ROUND(K41*30,0) -> 0 | P41: =L41*30 -> 0 | S41: =EXACT(B41,Total!B41) -> TRUE | T41: =SUM(D41+F41+H41+J41) -> 0 | W41: CAJA DE DISTRIBUCION DE 12 VIAS
B42: CAJA DE HERRAMIENTAS 13PCS | C42: =SUM(SUMIF(INDIRECT({"01";"02";"03";"04";"05";"06";"07"} & "!B:G"),$B42,INDIRECT({"01";"02";"03";"04";"05";"06";"07"} & "!G:G"))) -> 0 | D42: =SUM(SUMIF(INDIRECT({"01";"02";"03";"04";"05";"06";"07"} & "!B:I"),$B42,INDIRECT({"01";"02";"03";"04";"05";"06";"07"} & "!I:I"))) -> 0 | E42: {=SUM(SUMIF(INDIRECT({"08";"09";"10";"11";"12";"13";"14"} & "!B:G"),$B42,INDIRECT({"08";"09";"10";"11";"12";"13";"14"} & "!G:G")))} -> 2 | F42: {=SUM(SUMIF(INDIRECT({"08";"09";"10";"11";"12";"13";"14"} & "!B:I"),$B42,INDIRECT({"08";"09";"10";"11";"12";"13";"14"} & "!I:I")))} -> 40 | G42: {=SUM(SUMIF(INDIRECT({"15";"16";"17";"18";"19";"20";"21"} & "!B:G"),$B42,INDIRECT({"15";"16";"17";"18";"19";"20";"21"} & "!G:G")))} -> 0 | H42: {=SUM(SUMIF(INDIRECT({"15";"16";"17";"18";"19";"20";"21"} & "!B:I"),$B42,INDIRECT({"15";"16";"17";"18";"19";"20";"21"} & "!I:I")))} -> 0 | I42: {=SUM(SUMIF(INDIRECT({"22";"23";"24";"25";"26";"27";"28";"29";"30";"31"} & "!B:G"),$B42,INDIRECT({"22";"23";"24";"25";"26";"27";"28";"29";"30";"31"} & "!G:G")))} -> 0 | J42: {=SUM(SUMIF(INDIRECT({"22";"23";"24";"25";"26";"27";"28";"29";"30";"31"} & "!B:I"),$B42,INDIRECT({"22";"23";"24";"25";"26";"27";"28";"29";"30";"31"} & "!I:I")))} -> 0 | K42: =ROUND(SUM(C42,E42,G42,I42)/DAY(TODAY()),0) -> 2 | L42: =SUM(D42,F42,H42,J42)/DAY(TODAY()) -> 40 | M42: =K42*7 -> 14 | N42: =L42*7 -> 280 | O42: =ROUND(K42*30,0) -> 60 | P42: =L42*30 -> 1200 | S42: =EXACT(B42,Total!B42) -> TRUE | T42: =SUM(D42+F42+H42+J42) -> 40 | W42: CAJA DE HERRAMIENTAS 13PCS
...

Sheet Total
B3: CONTROL DE INVENTARIO | F3: ÁREA: | G3: NOVA
B4: A PRECIO DE VENTA
F5: No.
